2015-07-09 21:14:30,227 [WARNING] django.request: Not Found: /
2015-07-09 21:14:30,767 [WARNING] django.request: Not Found: /
2015-07-09 21:14:32,036 [WARNING] django.request: Not Found: /
2015-07-09 21:15:15,453 [WARNING] django.request: Not Found: /
2015-07-09 21:15:16,199 [WARNING] django.request: Not Found: /
2015-07-09 21:15:16,994 [WARNING] django.request: Not Found: /
2015-07-09 21:15:17,807 [WARNING] django.request: Not Found: /
2015-07-09 21:15:39,518 [WARNING] django.request: Not Found: /static/admin/css/base.css
2015-07-09 21:15:39,520 [WARNING] django.request: Not Found: /static/admin/css/login.css
2015-07-09 21:15:46,170 [WARNING] django.request: Not Found: /static/admin/css/base.css
2015-07-09 21:15:46,230 [WARNING] django.request: Not Found: /static/admin/css/dashboard.css
2015-07-09 21:15:50,825 [WARNING] django.request: Not Found: /static/admin/css/base.css
2015-07-09 21:15:50,829 [WARNING] django.request: Not Found: /static/admin/css/dashboard.css
2015-07-09 21:16:00,664 [WARNING] django.request: Not Found: /
2015-07-09 21:21:52,612 [WARNING] django.request: Not Found: /
2015-07-09 21:21:57,335 [WARNING] django.request: Not Found: /static/admin/css/dashboard.css
2015-07-09 21:21:57,336 [WARNING] django.request: Not Found: /static/admin/css/base.css
2015-07-09 21:23:48,549 [WARNING] django.request: Not Found: /static/admin/css/dashboard.css
2015-07-09 21:23:48,548 [WARNING] django.request: Not Found: /static/admin/css/base.css
2015-07-09 21:23:49,565 [WARNING] django.request: Not Found: /static/admin/css/base.css
2015-07-09 21:23:49,571 [WARNING] django.request: Not Found: /static/admin/css/dashboard.css
2015-07-09 21:23:50,365 [WARNING] django.request: Not Found: /static/admin/css/base.css
2015-07-09 21:23:50,374 [WARNING] django.request: Not Found: /static/admin/css/dashboard.css
2015-07-09 21:23:51,035 [WARNING] django.request: Not Found: /static/admin/css/base.css
2015-07-09 21:23:51,044 [WARNING] django.request: Not Found: /static/admin/css/dashboard.css
2015-07-09 21:23:51,674 [WARNING] django.request: Not Found: /static/admin/css/base.css
2015-07-09 21:23:51,681 [WARNING] django.request: Not Found: /static/admin/css/dashboard.css
2015-07-09 21:23:52,225 [WARNING] django.request: Not Found: /static/admin/css/base.css
2015-07-09 21:23:52,234 [WARNING] django.request: Not Found: /static/admin/css/dashboard.css
2015-07-09 21:23:52,855 [WARNING] django.request: Not Found: /static/admin/css/base.css
2015-07-09 21:23:52,864 [WARNING] django.request: Not Found: /static/admin/css/dashboard.css
2015-07-09 21:23:53,235 [WARNING] django.request: Not Found: /static/admin/css/base.css
2015-07-09 21:23:53,243 [WARNING] django.request: Not Found: /static/admin/css/dashboard.css
2015-07-09 21:23:56,614 [WARNING] django.request: Not Found: /
2015-07-09 21:24:00,215 [WARNING] django.request: Not Found: /static/admin/css/base.css
2015-07-09 21:24:00,216 [WARNING] django.request: Not Found: /static/admin/css/dashboard.css
2015-07-09 21:27:41,523 [ERROR] django.request: Internal Server Error: /admin/
Traceback (most recent call last):
  File "/usr/local/lib/python2.7/dist-packages/django/core/handlers/base.py", line 119, in get_response
    resolver_match = resolver.resolve(request.path_info)
  File "/usr/local/lib/python2.7/dist-packages/django/core/urlresolvers.py", line 366, in resolve
    for pattern in self.url_patterns:
  File "/usr/local/lib/python2.7/dist-packages/django/core/urlresolvers.py", line 402, in url_patterns
    patterns = getattr(self.urlconf_module, "urlpatterns", self.urlconf_module)
  File "/usr/local/lib/python2.7/dist-packages/django/core/urlresolvers.py", line 396, in urlconf_module
    self._urlconf_module = import_module(self.urlconf_name)
  File "/usr/lib/python2.7/importlib/__init__.py", line 37, in import_module
    __import__(name)
  File "/home/george/djangoSite/djangoSite/urls.py", line 21, in <module>
    ] + static(settings.STATIC_URL, document_root=settings.STATIC_ROOT),
NameError: name 'static' is not defined
2015-07-09 21:27:44,596 [ERROR] django.request: Internal Server Error: /admin/
Traceback (most recent call last):
  File "/usr/local/lib/python2.7/dist-packages/django/core/handlers/base.py", line 119, in get_response
    resolver_match = resolver.resolve(request.path_info)
  File "/usr/local/lib/python2.7/dist-packages/django/core/urlresolvers.py", line 366, in resolve
    for pattern in self.url_patterns:
  File "/usr/local/lib/python2.7/dist-packages/django/core/urlresolvers.py", line 402, in url_patterns
    patterns = getattr(self.urlconf_module, "urlpatterns", self.urlconf_module)
  File "/usr/local/lib/python2.7/dist-packages/django/core/urlresolvers.py", line 396, in urlconf_module
    self._urlconf_module = import_module(self.urlconf_name)
  File "/usr/lib/python2.7/importlib/__init__.py", line 37, in import_module
    __import__(name)
  File "/home/george/djangoSite/djangoSite/urls.py", line 21, in <module>
    ] + static(settings.STATIC_URL, document_root=settings.STATIC_ROOT),
NameError: name 'static' is not defined
2015-07-09 21:28:38,426 [ERROR] django.request: Internal Server Error: /admin/
Traceback (most recent call last):
  File "/usr/local/lib/python2.7/dist-packages/django/core/handlers/base.py", line 119, in get_response
    resolver_match = resolver.resolve(request.path_info)
  File "/usr/local/lib/python2.7/dist-packages/django/core/urlresolvers.py", line 366, in resolve
    for pattern in self.url_patterns:
  File "/usr/local/lib/python2.7/dist-packages/django/core/urlresolvers.py", line 402, in url_patterns
    patterns = getattr(self.urlconf_module, "urlpatterns", self.urlconf_module)
  File "/usr/local/lib/python2.7/dist-packages/django/core/urlresolvers.py", line 396, in urlconf_module
    self._urlconf_module = import_module(self.urlconf_name)
  File "/usr/lib/python2.7/importlib/__init__.py", line 37, in import_module
    __import__(name)
  File "/home/george/djangoSite/djangoSite/urls.py", line 22, in <module>
    ] + static(settings.STATIC_URL, document_root=settings.STATIC_ROOT),
NameError: name 'settings' is not defined
2015-07-09 21:28:39,412 [ERROR] django.request: Internal Server Error: /admin/
Traceback (most recent call last):
  File "/usr/local/lib/python2.7/dist-packages/django/core/handlers/base.py", line 119, in get_response
    resolver_match = resolver.resolve(request.path_info)
  File "/usr/local/lib/python2.7/dist-packages/django/core/urlresolvers.py", line 366, in resolve
    for pattern in self.url_patterns:
  File "/usr/local/lib/python2.7/dist-packages/django/core/urlresolvers.py", line 402, in url_patterns
    patterns = getattr(self.urlconf_module, "urlpatterns", self.urlconf_module)
  File "/usr/local/lib/python2.7/dist-packages/django/core/urlresolvers.py", line 396, in urlconf_module
    self._urlconf_module = import_module(self.urlconf_name)
  File "/usr/lib/python2.7/importlib/__init__.py", line 37, in import_module
    __import__(name)
  File "/home/george/djangoSite/djangoSite/urls.py", line 22, in <module>
    ] + static(settings.STATIC_URL, document_root=settings.STATIC_ROOT),
NameError: name 'settings' is not defined
2015-07-09 21:28:40,189 [ERROR] django.request: Internal Server Error: /admin/
Traceback (most recent call last):
  File "/usr/local/lib/python2.7/dist-packages/django/core/handlers/base.py", line 119, in get_response
    resolver_match = resolver.resolve(request.path_info)
  File "/usr/local/lib/python2.7/dist-packages/django/core/urlresolvers.py", line 366, in resolve
    for pattern in self.url_patterns:
  File "/usr/local/lib/python2.7/dist-packages/django/core/urlresolvers.py", line 402, in url_patterns
    patterns = getattr(self.urlconf_module, "urlpatterns", self.urlconf_module)
  File "/usr/local/lib/python2.7/dist-packages/django/core/urlresolvers.py", line 396, in urlconf_module
    self._urlconf_module = import_module(self.urlconf_name)
  File "/usr/lib/python2.7/importlib/__init__.py", line 37, in import_module
    __import__(name)
  File "/home/george/djangoSite/djangoSite/urls.py", line 22, in <module>
    ] + static(settings.STATIC_URL, document_root=settings.STATIC_ROOT),
NameError: name 'settings' is not defined
2015-07-09 21:28:41,081 [ERROR] django.request: Internal Server Error: /admin/
Traceback (most recent call last):
  File "/usr/local/lib/python2.7/dist-packages/django/core/handlers/base.py", line 119, in get_response
    resolver_match = resolver.resolve(request.path_info)
  File "/usr/local/lib/python2.7/dist-packages/django/core/urlresolvers.py", line 366, in resolve
    for pattern in self.url_patterns:
  File "/usr/local/lib/python2.7/dist-packages/django/core/urlresolvers.py", line 402, in url_patterns
    patterns = getattr(self.urlconf_module, "urlpatterns", self.urlconf_module)
  File "/usr/local/lib/python2.7/dist-packages/django/core/urlresolvers.py", line 396, in urlconf_module
    self._urlconf_module = import_module(self.urlconf_name)
  File "/usr/lib/python2.7/importlib/__init__.py", line 37, in import_module
    __import__(name)
  File "/home/george/djangoSite/djangoSite/urls.py", line 22, in <module>
    ] + static(settings.STATIC_URL, document_root=settings.STATIC_ROOT),
NameError: name 'settings' is not defined
2015-07-09 21:29:29,202 [ERROR] django.request: Internal Server Error: /admin/
Traceback (most recent call last):
  File "/usr/local/lib/python2.7/dist-packages/django/core/handlers/base.py", line 119, in get_response
    resolver_match = resolver.resolve(request.path_info)
  File "/usr/local/lib/python2.7/dist-packages/django/core/urlresolvers.py", line 368, in resolve
    sub_match = pattern.resolve(new_path)
AttributeError: 'list' object has no attribute 'resolve'
2015-07-09 21:29:30,177 [ERROR] django.request: Internal Server Error: /admin/
Traceback (most recent call last):
  File "/usr/local/lib/python2.7/dist-packages/django/core/handlers/base.py", line 119, in get_response
    resolver_match = resolver.resolve(request.path_info)
  File "/usr/local/lib/python2.7/dist-packages/django/core/urlresolvers.py", line 368, in resolve
    sub_match = pattern.resolve(new_path)
AttributeError: 'list' object has no attribute 'resolve'
2015-07-09 21:31:46,794 [ERROR] django.request: Internal Server Error: /admin/
Traceback (most recent call last):
  File "/usr/local/lib/python2.7/dist-packages/django/core/handlers/base.py", line 119, in get_response
    resolver_match = resolver.resolve(request.path_info)
  File "/usr/local/lib/python2.7/dist-packages/django/core/urlresolvers.py", line 366, in resolve
    for pattern in self.url_patterns:
  File "/usr/local/lib/python2.7/dist-packages/django/core/urlresolvers.py", line 402, in url_patterns
    patterns = getattr(self.urlconf_module, "urlpatterns", self.urlconf_module)
  File "/usr/local/lib/python2.7/dist-packages/django/core/urlresolvers.py", line 396, in urlconf_module
    self._urlconf_module = import_module(self.urlconf_name)
  File "/usr/lib/python2.7/importlib/__init__.py", line 37, in import_module
    __import__(name)
  File "/home/george/djangoSite/djangoSite/urls.py", line 21, in <module>
    urlpatterns = patterns('',
NameError: name 'patterns' is not defined
2015-07-09 21:32:52,604 [ERROR] django.request: Internal Server Error: /admin/
Traceback (most recent call last):
  File "/usr/local/lib/python2.7/dist-packages/django/core/handlers/base.py", line 119, in get_response
    resolver_match = resolver.resolve(request.path_info)
  File "/usr/local/lib/python2.7/dist-packages/django/core/urlresolvers.py", line 368, in resolve
    sub_match = pattern.resolve(new_path)
AttributeError: 'list' object has no attribute 'resolve'
2015-07-09 21:37:13,033 [WARNING] django.request: Not Found: /
2015-07-09 21:37:14,456 [WARNING] django.request: Not Found: /
2015-07-09 21:37:15,223 [WARNING] django.request: Not Found: /
2015-07-09 21:37:15,913 [WARNING] django.request: Not Found: /
2015-07-09 21:37:16,623 [WARNING] django.request: Not Found: /
2015-07-09 21:37:17,223 [WARNING] django.request: Not Found: /
2015-07-09 21:37:17,793 [WARNING] django.request: Not Found: /
2015-07-09 22:04:16,167 [ERROR] django.request: Internal Server Error: /admin/polls/question/
Traceback (most recent call last):
  File "/usr/local/lib/python2.7/dist-packages/django/core/handlers/base.py", line 164, in get_response
    response = response.render()
  File "/usr/local/lib/python2.7/dist-packages/django/template/response.py", line 158, in render
    self.content = self.rendered_content
  File "/usr/local/lib/python2.7/dist-packages/django/template/response.py", line 135, in rendered_content
    content = template.render(context, self._request)
  File "/usr/local/lib/python2.7/dist-packages/django/template/backends/django.py", line 74, in render
    return self.template.render(context)
  File "/usr/local/lib/python2.7/dist-packages/django/template/base.py", line 209, in render
    return self._render(context)
  File "/usr/local/lib/python2.7/dist-packages/django/template/base.py", line 201, in _render
    return self.nodelist.render(context)
  File "/usr/local/lib/python2.7/dist-packages/django/template/base.py", line 903, in render
    bit = self.render_node(node, context)
  File "/usr/local/lib/python2.7/dist-packages/django/template/debug.py", line 79, in render_node
    return node.render(context)
  File "/usr/local/lib/python2.7/dist-packages/django/template/loader_tags.py", line 135, in render
    return compiled_parent._render(context)
  File "/usr/local/lib/python2.7/dist-packages/django/template/base.py", line 201, in _render
    return self.nodelist.render(context)
  File "/usr/local/lib/python2.7/dist-packages/django/template/base.py", line 903, in render
    bit = self.render_node(node, context)
  File "/usr/local/lib/python2.7/dist-packages/django/template/debug.py", line 79, in render_node
    return node.render(context)
  File "/usr/local/lib/python2.7/dist-packages/django/template/loader_tags.py", line 135, in render
    return compiled_parent._render(context)
  File "/usr/local/lib/python2.7/dist-packages/django/template/base.py", line 201, in _render
    return self.nodelist.render(context)
  File "/usr/local/lib/python2.7/dist-packages/django/template/base.py", line 903, in render
    bit = self.render_node(node, context)
  File "/usr/local/lib/python2.7/dist-packages/django/template/debug.py", line 79, in render_node
    return node.render(context)
  File "/usr/local/lib/python2.7/dist-packages/django/template/loader_tags.py", line 65, in render
    result = block.nodelist.render(context)
  File "/usr/local/lib/python2.7/dist-packages/django/template/base.py", line 903, in render
    bit = self.render_node(node, context)
  File "/usr/local/lib/python2.7/dist-packages/django/template/debug.py", line 79, in render_node
    return node.render(context)
  File "/usr/local/lib/python2.7/dist-packages/django/template/loader_tags.py", line 65, in render
    result = block.nodelist.render(context)
  File "/usr/local/lib/python2.7/dist-packages/django/template/base.py", line 903, in render
    bit = self.render_node(node, context)
  File "/usr/local/lib/python2.7/dist-packages/django/template/debug.py", line 79, in render_node
    return node.render(context)
  File "/usr/local/lib/python2.7/dist-packages/django/template/base.py", line 1271, in render
    _dict = func(*resolved_args, **resolved_kwargs)
  File "/usr/local/lib/python2.7/dist-packages/django/contrib/admin/templatetags/admin_list.py", line 311, in result_list
    headers = list(result_headers(cl))
  File "/usr/local/lib/python2.7/dist-packages/django/contrib/admin/templatetags/admin_list.py", line 102, in result_headers
    return_attr=True
  File "/usr/local/lib/python2.7/dist-packages/django/contrib/admin/utils.py", line 337, in label_for_field
    raise AttributeError(message)
AttributeError: Unable to lookup 'was_published_recently' on Question or QuestionAdmin
2015-07-09 22:30:49,951 [WARNING] django.request: Not Found: /favicon.ico
2015-07-09 22:36:47,975 [WARNING] django.request: Not Found: /
2015-07-09 22:43:04,877 [ERROR] django.request: Internal Server Error: /
Traceback (most recent call last):
  File "/usr/local/lib/python2.7/dist-packages/django/core/handlers/base.py", line 119, in get_response
    resolver_match = resolver.resolve(request.path_info)
  File "/usr/local/lib/python2.7/dist-packages/django/core/urlresolvers.py", line 366, in resolve
    for pattern in self.url_patterns:
  File "/usr/local/lib/python2.7/dist-packages/django/core/urlresolvers.py", line 402, in url_patterns
    patterns = getattr(self.urlconf_module, "urlpatterns", self.urlconf_module)
  File "/usr/local/lib/python2.7/dist-packages/django/core/urlresolvers.py", line 396, in urlconf_module
    self._urlconf_module = import_module(self.urlconf_name)
  File "/usr/lib/python2.7/importlib/__init__.py", line 37, in import_module
    __import__(name)
  File "/home/george/djangoSite/djangoSite/urls.py", line 20, in <module>
    from django.views.generic.simple import direct_to_template
ImportError: No module named simple
2015-07-09 22:43:29,033 [ERROR] django.request: Internal Server Error: /admin/
Traceback (most recent call last):
  File "/usr/local/lib/python2.7/dist-packages/django/core/handlers/base.py", line 119, in get_response
    resolver_match = resolver.resolve(request.path_info)
  File "/usr/local/lib/python2.7/dist-packages/django/core/urlresolvers.py", line 366, in resolve
    for pattern in self.url_patterns:
  File "/usr/local/lib/python2.7/dist-packages/django/core/urlresolvers.py", line 402, in url_patterns
    patterns = getattr(self.urlconf_module, "urlpatterns", self.urlconf_module)
  File "/usr/local/lib/python2.7/dist-packages/django/core/urlresolvers.py", line 396, in urlconf_module
    self._urlconf_module = import_module(self.urlconf_name)
  File "/usr/lib/python2.7/importlib/__init__.py", line 37, in import_module
    __import__(name)
  File "/home/george/djangoSite/djangoSite/urls.py", line 20, in <module>
    from django.views.generic.simple import direct_to_template
ImportError: No module named simple
2015-07-09 22:46:39,733 [ERROR] django.request: Internal Server Error: /
Traceback (most recent call last):
  File "/usr/local/lib/python2.7/dist-packages/django/core/handlers/base.py", line 119, in get_response
    resolver_match = resolver.resolve(request.path_info)
  File "/usr/local/lib/python2.7/dist-packages/django/core/urlresolvers.py", line 366, in resolve
    for pattern in self.url_patterns:
  File "/usr/local/lib/python2.7/dist-packages/django/core/urlresolvers.py", line 402, in url_patterns
    patterns = getattr(self.urlconf_module, "urlpatterns", self.urlconf_module)
  File "/usr/local/lib/python2.7/dist-packages/django/core/urlresolvers.py", line 396, in urlconf_module
    self._urlconf_module = import_module(self.urlconf_name)
  File "/usr/lib/python2.7/importlib/__init__.py", line 37, in import_module
    __import__(name)
  File "/home/george/djangoSite/djangoSite/urls.py", line 20, in <module>
    from django.views.generic.simple import direct_to_template
ImportError: No module named simple
2015-07-09 22:46:41,527 [ERROR] django.request: Internal Server Error: /
Traceback (most recent call last):
  File "/usr/local/lib/python2.7/dist-packages/django/core/handlers/base.py", line 119, in get_response
    resolver_match = resolver.resolve(request.path_info)
  File "/usr/local/lib/python2.7/dist-packages/django/core/urlresolvers.py", line 366, in resolve
    for pattern in self.url_patterns:
  File "/usr/local/lib/python2.7/dist-packages/django/core/urlresolvers.py", line 402, in url_patterns
    patterns = getattr(self.urlconf_module, "urlpatterns", self.urlconf_module)
  File "/usr/local/lib/python2.7/dist-packages/django/core/urlresolvers.py", line 396, in urlconf_module
    self._urlconf_module = import_module(self.urlconf_name)
  File "/usr/lib/python2.7/importlib/__init__.py", line 37, in import_module
    __import__(name)
  File "/home/george/djangoSite/djangoSite/urls.py", line 20, in <module>
    from django.views.generic.simple import direct_to_template
ImportError: No module named simple
2015-07-09 22:47:43,459 [ERROR] django.request: Internal Server Error: /
Traceback (most recent call last):
  File "/usr/local/lib/python2.7/dist-packages/django/core/handlers/base.py", line 119, in get_response
    resolver_match = resolver.resolve(request.path_info)
  File "/usr/local/lib/python2.7/dist-packages/django/core/urlresolvers.py", line 366, in resolve
    for pattern in self.url_patterns:
  File "/usr/local/lib/python2.7/dist-packages/django/core/urlresolvers.py", line 402, in url_patterns
    patterns = getattr(self.urlconf_module, "urlpatterns", self.urlconf_module)
  File "/usr/local/lib/python2.7/dist-packages/django/core/urlresolvers.py", line 396, in urlconf_module
    self._urlconf_module = import_module(self.urlconf_name)
  File "/usr/lib/python2.7/importlib/__init__.py", line 37, in import_module
    __import__(name)
  File "/home/george/djangoSite/djangoSite/urls.py", line 20, in <module>
    from django.views.generic.simple import direct_to_template, simple
ImportError: No module named simple
2015-07-09 22:47:45,238 [ERROR] django.request: Internal Server Error: /
Traceback (most recent call last):
  File "/usr/local/lib/python2.7/dist-packages/django/core/handlers/base.py", line 119, in get_response
    resolver_match = resolver.resolve(request.path_info)
  File "/usr/local/lib/python2.7/dist-packages/django/core/urlresolvers.py", line 366, in resolve
    for pattern in self.url_patterns:
  File "/usr/local/lib/python2.7/dist-packages/django/core/urlresolvers.py", line 402, in url_patterns
    patterns = getattr(self.urlconf_module, "urlpatterns", self.urlconf_module)
  File "/usr/local/lib/python2.7/dist-packages/django/core/urlresolvers.py", line 396, in urlconf_module
    self._urlconf_module = import_module(self.urlconf_name)
  File "/usr/lib/python2.7/importlib/__init__.py", line 37, in import_module
    __import__(name)
  File "/home/george/djangoSite/djangoSite/urls.py", line 20, in <module>
    from django.views.generic.simple import direct_to_template, simple
ImportError: No module named simple
2015-07-09 22:47:46,165 [ERROR] django.request: Internal Server Error: /
Traceback (most recent call last):
  File "/usr/local/lib/python2.7/dist-packages/django/core/handlers/base.py", line 119, in get_response
    resolver_match = resolver.resolve(request.path_info)
  File "/usr/local/lib/python2.7/dist-packages/django/core/urlresolvers.py", line 366, in resolve
    for pattern in self.url_patterns:
  File "/usr/local/lib/python2.7/dist-packages/django/core/urlresolvers.py", line 402, in url_patterns
    patterns = getattr(self.urlconf_module, "urlpatterns", self.urlconf_module)
  File "/usr/local/lib/python2.7/dist-packages/django/core/urlresolvers.py", line 396, in urlconf_module
    self._urlconf_module = import_module(self.urlconf_name)
  File "/usr/lib/python2.7/importlib/__init__.py", line 37, in import_module
    __import__(name)
  File "/home/george/djangoSite/djangoSite/urls.py", line 20, in <module>
    from django.views.generic.simple import direct_to_template, simple
ImportError: No module named simple
2015-07-09 22:49:50,862 [ERROR] django.request: Internal Server Error: /
Traceback (most recent call last):
  File "/usr/local/lib/python2.7/dist-packages/django/core/handlers/base.py", line 119, in get_response
    resolver_match = resolver.resolve(request.path_info)
  File "/usr/local/lib/python2.7/dist-packages/django/core/urlresolvers.py", line 366, in resolve
    for pattern in self.url_patterns:
  File "/usr/local/lib/python2.7/dist-packages/django/core/urlresolvers.py", line 402, in url_patterns
    patterns = getattr(self.urlconf_module, "urlpatterns", self.urlconf_module)
  File "/usr/local/lib/python2.7/dist-packages/django/core/urlresolvers.py", line 396, in urlconf_module
    self._urlconf_module = import_module(self.urlconf_name)
  File "/usr/lib/python2.7/importlib/__init__.py", line 37, in import_module
    __import__(name)
  File "/home/george/djangoSite/djangoSite/urls.py", line 23, in <module>
    (r"^$", Template.as_view(template_name="index.html")),
NameError: name 'Template' is not defined
2015-07-09 23:15:19,114 [WARNING] django.request: Not Found: /favicon.ico
2015-07-10 01:44:03,479 [WARNING] django.request: Not Found: /favicon.ico
2015-07-10 02:08:31,525 [ERROR] django.request: Internal Server Error: /
Traceback (most recent call last):
  File "/usr/local/lib/python2.7/dist-packages/django/core/handlers/base.py", line 119, in get_response
    resolver_match = resolver.resolve(request.path_info)
  File "/usr/local/lib/python2.7/dist-packages/django/core/urlresolvers.py", line 366, in resolve
    for pattern in self.url_patterns:
  File "/usr/local/lib/python2.7/dist-packages/django/core/urlresolvers.py", line 402, in url_patterns
    patterns = getattr(self.urlconf_module, "urlpatterns", self.urlconf_module)
  File "/usr/local/lib/python2.7/dist-packages/django/core/urlresolvers.py", line 396, in urlconf_module
    self._urlconf_module = import_module(self.urlconf_name)
  File "/usr/lib/python2.7/importlib/__init__.py", line 37, in import_module
    __import__(name)
  File "/home/george/djangoSite/djangoSite/urls.py", line 24, in <module>
    url(r'^polls/', include('polls.urls')),
  File "/usr/local/lib/python2.7/dist-packages/django/conf/urls/__init__.py", line 33, in include
    urlconf_module = import_module(urlconf_module)
  File "/usr/lib/python2.7/importlib/__init__.py", line 37, in import_module
    __import__(name)
  File "/home/george/djangoSite/polls/urls.py", line 3, in <module>
    from . import views
  File "/home/george/djangoSite/polls/views.py", line 5
    return HttpResponse("Hello World, this is the polls index.")
         ^
IndentationError: expected an indented block
2015-07-10 02:08:32,241 [ERROR] django.request: Internal Server Error: /favicon.ico
Traceback (most recent call last):
  File "/usr/local/lib/python2.7/dist-packages/django/core/handlers/base.py", line 108, in get_response
    response = middleware_method(request)
  File "/usr/local/lib/python2.7/dist-packages/django/middleware/common.py", line 74, in process_request
    if (not urlresolvers.is_valid_path(request.path_info, urlconf) and
  File "/usr/local/lib/python2.7/dist-packages/django/core/urlresolvers.py", line 647, in is_valid_path
    resolve(path, urlconf)
  File "/usr/local/lib/python2.7/dist-packages/django/core/urlresolvers.py", line 522, in resolve
    return get_resolver(urlconf).resolve(path)
  File "/usr/local/lib/python2.7/dist-packages/django/core/urlresolvers.py", line 366, in resolve
    for pattern in self.url_patterns:
  File "/usr/local/lib/python2.7/dist-packages/django/core/urlresolvers.py", line 402, in url_patterns
    patterns = getattr(self.urlconf_module, "urlpatterns", self.urlconf_module)
  File "/usr/local/lib/python2.7/dist-packages/django/core/urlresolvers.py", line 396, in urlconf_module
    self._urlconf_module = import_module(self.urlconf_name)
  File "/usr/lib/python2.7/importlib/__init__.py", line 37, in import_module
    __import__(name)
  File "/home/george/djangoSite/djangoSite/urls.py", line 24, in <module>
    url(r'^polls/', include('polls.urls')),
  File "/usr/local/lib/python2.7/dist-packages/django/conf/urls/__init__.py", line 33, in include
    urlconf_module = import_module(urlconf_module)
  File "/usr/lib/python2.7/importlib/__init__.py", line 37, in import_module
    __import__(name)
  File "/home/george/djangoSite/polls/urls.py", line 3, in <module>
    from . import views
  File "/home/george/djangoSite/polls/views.py", line 5
    return HttpResponse("Hello World, this is the polls index.")
         ^
IndentationError: expected an indented block
2015-07-10 02:09:17,387 [WARNING] django.request: Not Found: /favicon.ico
2015-07-10 03:16:03,196 [WARNING] django.request: Not Found: /favicon.ico
2015-07-10 03:19:29,178 [ERROR] django.request: Internal Server Error: /polls/send
Traceback (most recent call last):
  File "/usr/local/lib/python2.7/dist-packages/django/core/handlers/base.py", line 132, in get_response
    response = wrapped_callback(request, *callback_args, **callback_kwargs)
  File "/home/george/djangoSite/polls/views.py", line 8, in send
    mylog.lg
NameError: global name 'mylog' is not defined
2015-07-10 03:31:44,140 [ERROR] django.request: Internal Server Error: /polls/send
Traceback (most recent call last):
  File "/usr/local/lib/python2.7/dist-packages/django/core/handlers/base.py", line 151, in get_response
    % (callback.__module__, view_name))
ValueError: The view polls.views.send didn't return an HttpResponse object. It returned None instead.
2015-07-10 03:56:13,016 [WARNING] django.request: Not Found: /testproxy.php
2015-07-10 05:04:58,056 [WARNING] django.request: Not Found: /CFIDE/administrator/
2015-07-10 14:58:21,449 [WARNING] django.request: Not Found: /favicon.ico
2015-07-10 17:41:47,594 [WARNING] django.request: Not Found: /favicon.ico
2015-07-10 18:04:32,766 [ERROR] django.request: Internal Server Error: /
Traceback (most recent call last):
  File "/usr/local/lib/python2.7/dist-packages/django/core/handlers/base.py", line 119, in get_response
    resolver_match = resolver.resolve(request.path_info)
  File "/usr/local/lib/python2.7/dist-packages/django/core/urlresolvers.py", line 366, in resolve
    for pattern in self.url_patterns:
  File "/usr/local/lib/python2.7/dist-packages/django/core/urlresolvers.py", line 402, in url_patterns
    patterns = getattr(self.urlconf_module, "urlpatterns", self.urlconf_module)
  File "/usr/local/lib/python2.7/dist-packages/django/core/urlresolvers.py", line 396, in urlconf_module
    self._urlconf_module = import_module(self.urlconf_name)
  File "/usr/lib/python2.7/importlib/__init__.py", line 37, in import_module
    __import__(name)
  File "/home/george/djangoSite/djangoSite/urls.py", line 24, in <module>
    url(r'^polls/', include('polls.urls')),
  File "/usr/local/lib/python2.7/dist-packages/django/conf/urls/__init__.py", line 33, in include
    urlconf_module = import_module(urlconf_module)
  File "/usr/lib/python2.7/importlib/__init__.py", line 37, in import_module
    __import__(name)
  File "/home/george/djangoSite/polls/urls.py", line 10
    url(r'(?P<question_id>[0-9]+)/vote/$', views.vote, name='vote')
      ^
SyntaxError: invalid syntax
2015-07-10 18:20:46,264 [WARNING] django.request: Not Found: /poop/polls/3/results/
2015-07-10 19:14:37,572 [ERROR] django.request: Internal Server Error: /polls/
Traceback (most recent call last):
  File "/usr/local/lib/python2.7/dist-packages/django/core/handlers/base.py", line 132, in get_response
    response = wrapped_callback(request, *callback_args, **callback_kwargs)
  File "/home/george/djangoSite/polls/views.py", line 11, in index
    return render(request, 'polls/index', context)
  File "/usr/local/lib/python2.7/dist-packages/django/shortcuts.py", line 67, in render
    template_name, context, request=request, using=using)
  File "/usr/local/lib/python2.7/dist-packages/django/template/loader.py", line 98, in render_to_string
    template = get_template(template_name, using=using)
  File "/usr/local/lib/python2.7/dist-packages/django/template/loader.py", line 46, in get_template
    raise TemplateDoesNotExist(template_name)
TemplateDoesNotExist: polls/index
2015-07-10 19:14:59,924 [ERROR] django.request: Internal Server Error: /polls/
Traceback (most recent call last):
  File "/usr/local/lib/python2.7/dist-packages/django/core/handlers/base.py", line 132, in get_response
    response = wrapped_callback(request, *callback_args, **callback_kwargs)
  File "/home/george/djangoSite/polls/views.py", line 11, in index
    return render(request, 'polls/index.html', context)
  File "/usr/local/lib/python2.7/dist-packages/django/shortcuts.py", line 67, in render
    template_name, context, request=request, using=using)
  File "/usr/local/lib/python2.7/dist-packages/django/template/loader.py", line 98, in render_to_string
    template = get_template(template_name, using=using)
  File "/usr/local/lib/python2.7/dist-packages/django/template/loader.py", line 46, in get_template
    raise TemplateDoesNotExist(template_name)
TemplateDoesNotExist: polls/index
2015-07-10 19:15:01,068 [ERROR] django.request: Internal Server Error: /polls/
Traceback (most recent call last):
  File "/usr/local/lib/python2.7/dist-packages/django/core/handlers/base.py", line 132, in get_response
    response = wrapped_callback(request, *callback_args, **callback_kwargs)
  File "/home/george/djangoSite/polls/views.py", line 11, in index
    return render(request, 'polls/index.html', context)
  File "/usr/local/lib/python2.7/dist-packages/django/shortcuts.py", line 67, in render
    template_name, context, request=request, using=using)
  File "/usr/local/lib/python2.7/dist-packages/django/template/loader.py", line 98, in render_to_string
    template = get_template(template_name, using=using)
  File "/usr/local/lib/python2.7/dist-packages/django/template/loader.py", line 46, in get_template
    raise TemplateDoesNotExist(template_name)
TemplateDoesNotExist: polls/index
2015-07-10 19:15:03,192 [ERROR] django.request: Internal Server Error: /polls/
Traceback (most recent call last):
  File "/usr/local/lib/python2.7/dist-packages/django/core/handlers/base.py", line 132, in get_response
    response = wrapped_callback(request, *callback_args, **callback_kwargs)
  File "/home/george/djangoSite/polls/views.py", line 11, in index
    return render(request, 'polls/index.html', context)
  File "/usr/local/lib/python2.7/dist-packages/django/shortcuts.py", line 67, in render
    template_name, context, request=request, using=using)
  File "/usr/local/lib/python2.7/dist-packages/django/template/loader.py", line 98, in render_to_string
    template = get_template(template_name, using=using)
  File "/usr/local/lib/python2.7/dist-packages/django/template/loader.py", line 46, in get_template
    raise TemplateDoesNotExist(template_name)
TemplateDoesNotExist: polls/index
2015-07-10 19:22:24,050 [WARNING] django.request: Not Found: /polls/5/
2015-07-10 19:25:09,229 [WARNING] django.request: Not Found: /polls/5/
2015-07-10 19:25:10,431 [WARNING] django.request: Not Found: /polls/5/
2015-07-10 19:25:11,309 [WARNING] django.request: Not Found: /polls/5/
2015-07-10 19:29:11,194 [WARNING] django.request: Not Found: /polls/5/
2015-07-10 19:37:16,172 [ERROR] django.request: Internal Server Error: /polls/
Traceback (most recent call last):
  File "/usr/local/lib/python2.7/dist-packages/django/core/handlers/base.py", line 119, in get_response
    resolver_match = resolver.resolve(request.path_info)
  File "/usr/local/lib/python2.7/dist-packages/django/core/urlresolvers.py", line 366, in resolve
    for pattern in self.url_patterns:
  File "/usr/local/lib/python2.7/dist-packages/django/core/urlresolvers.py", line 402, in url_patterns
    patterns = getattr(self.urlconf_module, "urlpatterns", self.urlconf_module)
  File "/usr/local/lib/python2.7/dist-packages/django/core/urlresolvers.py", line 396, in urlconf_module
    self._urlconf_module = import_module(self.urlconf_name)
  File "/usr/lib/python2.7/importlib/__init__.py", line 37, in import_module
    __import__(name)
  File "/home/george/djangoSite/djangoSite/urls.py", line 24, in <module>
    url(r'^polls/', include('polls.urls'), namespace='polls'),
TypeError: url() got an unexpected keyword argument 'namespace'
