2015-07-09 21:14:30,227 [WARNING] django.request: Not Found: /
2015-07-09 21:14:30,767 [WARNING] django.request: Not Found: /
2015-07-09 21:14:32,036 [WARNING] django.request: Not Found: /
2015-07-09 21:15:15,453 [WARNING] django.request: Not Found: /
2015-07-09 21:15:16,199 [WARNING] django.request: Not Found: /
2015-07-09 21:15:16,994 [WARNING] django.request: Not Found: /
2015-07-09 21:15:17,807 [WARNING] django.request: Not Found: /
2015-07-09 21:15:39,518 [WARNING] django.request: Not Found: /static/admin/css/base.css
2015-07-09 21:15:39,520 [WARNING] django.request: Not Found: /static/admin/css/login.css
2015-07-09 21:15:46,170 [WARNING] django.request: Not Found: /static/admin/css/base.css
2015-07-09 21:15:46,230 [WARNING] django.request: Not Found: /static/admin/css/dashboard.css
2015-07-09 21:15:50,825 [WARNING] django.request: Not Found: /static/admin/css/base.css
2015-07-09 21:15:50,829 [WARNING] django.request: Not Found: /static/admin/css/dashboard.css
2015-07-09 21:16:00,664 [WARNING] django.request: Not Found: /
2015-07-09 21:21:52,612 [WARNING] django.request: Not Found: /
2015-07-09 21:21:57,335 [WARNING] django.request: Not Found: /static/admin/css/dashboard.css
2015-07-09 21:21:57,336 [WARNING] django.request: Not Found: /static/admin/css/base.css
2015-07-09 21:23:48,549 [WARNING] django.request: Not Found: /static/admin/css/dashboard.css
2015-07-09 21:23:48,548 [WARNING] django.request: Not Found: /static/admin/css/base.css
2015-07-09 21:23:49,565 [WARNING] django.request: Not Found: /static/admin/css/base.css
2015-07-09 21:23:49,571 [WARNING] django.request: Not Found: /static/admin/css/dashboard.css
2015-07-09 21:23:50,365 [WARNING] django.request: Not Found: /static/admin/css/base.css
2015-07-09 21:23:50,374 [WARNING] django.request: Not Found: /static/admin/css/dashboard.css
2015-07-09 21:23:51,035 [WARNING] django.request: Not Found: /static/admin/css/base.css
2015-07-09 21:23:51,044 [WARNING] django.request: Not Found: /static/admin/css/dashboard.css
2015-07-09 21:23:51,674 [WARNING] django.request: Not Found: /static/admin/css/base.css
2015-07-09 21:23:51,681 [WARNING] django.request: Not Found: /static/admin/css/dashboard.css
2015-07-09 21:23:52,225 [WARNING] django.request: Not Found: /static/admin/css/base.css
2015-07-09 21:23:52,234 [WARNING] django.request: Not Found: /static/admin/css/dashboard.css
2015-07-09 21:23:52,855 [WARNING] django.request: Not Found: /static/admin/css/base.css
2015-07-09 21:23:52,864 [WARNING] django.request: Not Found: /static/admin/css/dashboard.css
2015-07-09 21:23:53,235 [WARNING] django.request: Not Found: /static/admin/css/base.css
2015-07-09 21:23:53,243 [WARNING] django.request: Not Found: /static/admin/css/dashboard.css
2015-07-09 21:23:56,614 [WARNING] django.request: Not Found: /
2015-07-09 21:24:00,215 [WARNING] django.request: Not Found: /static/admin/css/base.css
2015-07-09 21:24:00,216 [WARNING] django.request: Not Found: /static/admin/css/dashboard.css
2015-07-09 21:27:41,523 [ERROR] django.request: Internal Server Error: /admin/
Traceback (most recent call last):
  File "/usr/local/lib/python2.7/dist-packages/django/core/handlers/base.py", line 119, in get_response
    resolver_match = resolver.resolve(request.path_info)
  File "/usr/local/lib/python2.7/dist-packages/django/core/urlresolvers.py", line 366, in resolve
    for pattern in self.url_patterns:
  File "/usr/local/lib/python2.7/dist-packages/django/core/urlresolvers.py", line 402, in url_patterns
    patterns = getattr(self.urlconf_module, "urlpatterns", self.urlconf_module)
  File "/usr/local/lib/python2.7/dist-packages/django/core/urlresolvers.py", line 396, in urlconf_module
    self._urlconf_module = import_module(self.urlconf_name)
  File "/usr/lib/python2.7/importlib/__init__.py", line 37, in import_module
    __import__(name)
  File "/home/george/djangoSite/djangoSite/urls.py", line 21, in <module>
    ] + static(settings.STATIC_URL, document_root=settings.STATIC_ROOT),
NameError: name 'static' is not defined
2015-07-09 21:27:44,596 [ERROR] django.request: Internal Server Error: /admin/
Traceback (most recent call last):
  File "/usr/local/lib/python2.7/dist-packages/django/core/handlers/base.py", line 119, in get_response
    resolver_match = resolver.resolve(request.path_info)
  File "/usr/local/lib/python2.7/dist-packages/django/core/urlresolvers.py", line 366, in resolve
    for pattern in self.url_patterns:
  File "/usr/local/lib/python2.7/dist-packages/django/core/urlresolvers.py", line 402, in url_patterns
    patterns = getattr(self.urlconf_module, "urlpatterns", self.urlconf_module)
  File "/usr/local/lib/python2.7/dist-packages/django/core/urlresolvers.py", line 396, in urlconf_module
    self._urlconf_module = import_module(self.urlconf_name)
  File "/usr/lib/python2.7/importlib/__init__.py", line 37, in import_module
    __import__(name)
  File "/home/george/djangoSite/djangoSite/urls.py", line 21, in <module>
    ] + static(settings.STATIC_URL, document_root=settings.STATIC_ROOT),
NameError: name 'static' is not defined
2015-07-09 21:28:38,426 [ERROR] django.request: Internal Server Error: /admin/
Traceback (most recent call last):
  File "/usr/local/lib/python2.7/dist-packages/django/core/handlers/base.py", line 119, in get_response
    resolver_match = resolver.resolve(request.path_info)
  File "/usr/local/lib/python2.7/dist-packages/django/core/urlresolvers.py", line 366, in resolve
    for pattern in self.url_patterns:
  File "/usr/local/lib/python2.7/dist-packages/django/core/urlresolvers.py", line 402, in url_patterns
    patterns = getattr(self.urlconf_module, "urlpatterns", self.urlconf_module)
  File "/usr/local/lib/python2.7/dist-packages/django/core/urlresolvers.py", line 396, in urlconf_module
    self._urlconf_module = import_module(self.urlconf_name)
  File "/usr/lib/python2.7/importlib/__init__.py", line 37, in import_module
    __import__(name)
  File "/home/george/djangoSite/djangoSite/urls.py", line 22, in <module>
    ] + static(settings.STATIC_URL, document_root=settings.STATIC_ROOT),
NameError: name 'settings' is not defined
2015-07-09 21:28:39,412 [ERROR] django.request: Internal Server Error: /admin/
Traceback (most recent call last):
  File "/usr/local/lib/python2.7/dist-packages/django/core/handlers/base.py", line 119, in get_response
    resolver_match = resolver.resolve(request.path_info)
  File "/usr/local/lib/python2.7/dist-packages/django/core/urlresolvers.py", line 366, in resolve
    for pattern in self.url_patterns:
  File "/usr/local/lib/python2.7/dist-packages/django/core/urlresolvers.py", line 402, in url_patterns
    patterns = getattr(self.urlconf_module, "urlpatterns", self.urlconf_module)
  File "/usr/local/lib/python2.7/dist-packages/django/core/urlresolvers.py", line 396, in urlconf_module
    self._urlconf_module = import_module(self.urlconf_name)
  File "/usr/lib/python2.7/importlib/__init__.py", line 37, in import_module
    __import__(name)
  File "/home/george/djangoSite/djangoSite/urls.py", line 22, in <module>
    ] + static(settings.STATIC_URL, document_root=settings.STATIC_ROOT),
NameError: name 'settings' is not defined
2015-07-09 21:28:40,189 [ERROR] django.request: Internal Server Error: /admin/
Traceback (most recent call last):
  File "/usr/local/lib/python2.7/dist-packages/django/core/handlers/base.py", line 119, in get_response
    resolver_match = resolver.resolve(request.path_info)
  File "/usr/local/lib/python2.7/dist-packages/django/core/urlresolvers.py", line 366, in resolve
    for pattern in self.url_patterns:
  File "/usr/local/lib/python2.7/dist-packages/django/core/urlresolvers.py", line 402, in url_patterns
    patterns = getattr(self.urlconf_module, "urlpatterns", self.urlconf_module)
  File "/usr/local/lib/python2.7/dist-packages/django/core/urlresolvers.py", line 396, in urlconf_module
    self._urlconf_module = import_module(self.urlconf_name)
  File "/usr/lib/python2.7/importlib/__init__.py", line 37, in import_module
    __import__(name)
  File "/home/george/djangoSite/djangoSite/urls.py", line 22, in <module>
    ] + static(settings.STATIC_URL, document_root=settings.STATIC_ROOT),
NameError: name 'settings' is not defined
2015-07-09 21:28:41,081 [ERROR] django.request: Internal Server Error: /admin/
Traceback (most recent call last):
  File "/usr/local/lib/python2.7/dist-packages/django/core/handlers/base.py", line 119, in get_response
    resolver_match = resolver.resolve(request.path_info)
  File "/usr/local/lib/python2.7/dist-packages/django/core/urlresolvers.py", line 366, in resolve
    for pattern in self.url_patterns:
  File "/usr/local/lib/python2.7/dist-packages/django/core/urlresolvers.py", line 402, in url_patterns
    patterns = getattr(self.urlconf_module, "urlpatterns", self.urlconf_module)
  File "/usr/local/lib/python2.7/dist-packages/django/core/urlresolvers.py", line 396, in urlconf_module
    self._urlconf_module = import_module(self.urlconf_name)
  File "/usr/lib/python2.7/importlib/__init__.py", line 37, in import_module
    __import__(name)
  File "/home/george/djangoSite/djangoSite/urls.py", line 22, in <module>
    ] + static(settings.STATIC_URL, document_root=settings.STATIC_ROOT),
NameError: name 'settings' is not defined
2015-07-09 21:29:29,202 [ERROR] django.request: Internal Server Error: /admin/
Traceback (most recent call last):
  File "/usr/local/lib/python2.7/dist-packages/django/core/handlers/base.py", line 119, in get_response
    resolver_match = resolver.resolve(request.path_info)
  File "/usr/local/lib/python2.7/dist-packages/django/core/urlresolvers.py", line 368, in resolve
    sub_match = pattern.resolve(new_path)
AttributeError: 'list' object has no attribute 'resolve'
2015-07-09 21:29:30,177 [ERROR] django.request: Internal Server Error: /admin/
Traceback (most recent call last):
  File "/usr/local/lib/python2.7/dist-packages/django/core/handlers/base.py", line 119, in get_response
    resolver_match = resolver.resolve(request.path_info)
  File "/usr/local/lib/python2.7/dist-packages/django/core/urlresolvers.py", line 368, in resolve
    sub_match = pattern.resolve(new_path)
AttributeError: 'list' object has no attribute 'resolve'
2015-07-09 21:31:46,794 [ERROR] django.request: Internal Server Error: /admin/
Traceback (most recent call last):
  File "/usr/local/lib/python2.7/dist-packages/django/core/handlers/base.py", line 119, in get_response
    resolver_match = resolver.resolve(request.path_info)
  File "/usr/local/lib/python2.7/dist-packages/django/core/urlresolvers.py", line 366, in resolve
    for pattern in self.url_patterns:
  File "/usr/local/lib/python2.7/dist-packages/django/core/urlresolvers.py", line 402, in url_patterns
    patterns = getattr(self.urlconf_module, "urlpatterns", self.urlconf_module)
  File "/usr/local/lib/python2.7/dist-packages/django/core/urlresolvers.py", line 396, in urlconf_module
    self._urlconf_module = import_module(self.urlconf_name)
  File "/usr/lib/python2.7/importlib/__init__.py", line 37, in import_module
    __import__(name)
  File "/home/george/djangoSite/djangoSite/urls.py", line 21, in <module>
    urlpatterns = patterns('',
NameError: name 'patterns' is not defined
2015-07-09 21:32:52,604 [ERROR] django.request: Internal Server Error: /admin/
Traceback (most recent call last):
  File "/usr/local/lib/python2.7/dist-packages/django/core/handlers/base.py", line 119, in get_response
    resolver_match = resolver.resolve(request.path_info)
  File "/usr/local/lib/python2.7/dist-packages/django/core/urlresolvers.py", line 368, in resolve
    sub_match = pattern.resolve(new_path)
AttributeError: 'list' object has no attribute 'resolve'
2015-07-09 21:37:13,033 [WARNING] django.request: Not Found: /
2015-07-09 21:37:14,456 [WARNING] django.request: Not Found: /
2015-07-09 21:37:15,223 [WARNING] django.request: Not Found: /
2015-07-09 21:37:15,913 [WARNING] django.request: Not Found: /
2015-07-09 21:37:16,623 [WARNING] django.request: Not Found: /
2015-07-09 21:37:17,223 [WARNING] django.request: Not Found: /
2015-07-09 21:37:17,793 [WARNING] django.request: Not Found: /
2015-07-09 22:04:16,167 [ERROR] django.request: Internal Server Error: /admin/polls/question/
Traceback (most recent call last):
  File "/usr/local/lib/python2.7/dist-packages/django/core/handlers/base.py", line 164, in get_response
    response = response.render()
  File "/usr/local/lib/python2.7/dist-packages/django/template/response.py", line 158, in render
    self.content = self.rendered_content
  File "/usr/local/lib/python2.7/dist-packages/django/template/response.py", line 135, in rendered_content
    content = template.render(context, self._request)
  File "/usr/local/lib/python2.7/dist-packages/django/template/backends/django.py", line 74, in render
    return self.template.render(context)
  File "/usr/local/lib/python2.7/dist-packages/django/template/base.py", line 209, in render
    return self._render(context)
  File "/usr/local/lib/python2.7/dist-packages/django/template/base.py", line 201, in _render
    return self.nodelist.render(context)
  File "/usr/local/lib/python2.7/dist-packages/django/template/base.py", line 903, in render
    bit = self.render_node(node, context)
  File "/usr/local/lib/python2.7/dist-packages/django/template/debug.py", line 79, in render_node
    return node.render(context)
  File "/usr/local/lib/python2.7/dist-packages/django/template/loader_tags.py", line 135, in render
    return compiled_parent._render(context)
  File "/usr/local/lib/python2.7/dist-packages/django/template/base.py", line 201, in _render
    return self.nodelist.render(context)
  File "/usr/local/lib/python2.7/dist-packages/django/template/base.py", line 903, in render
    bit = self.render_node(node, context)
  File "/usr/local/lib/python2.7/dist-packages/django/template/debug.py", line 79, in render_node
    return node.render(context)
  File "/usr/local/lib/python2.7/dist-packages/django/template/loader_tags.py", line 135, in render
    return compiled_parent._render(context)
  File "/usr/local/lib/python2.7/dist-packages/django/template/base.py", line 201, in _render
    return self.nodelist.render(context)
  File "/usr/local/lib/python2.7/dist-packages/django/template/base.py", line 903, in render
    bit = self.render_node(node, context)
  File "/usr/local/lib/python2.7/dist-packages/django/template/debug.py", line 79, in render_node
    return node.render(context)
  File "/usr/local/lib/python2.7/dist-packages/django/template/loader_tags.py", line 65, in render
    result = block.nodelist.render(context)
  File "/usr/local/lib/python2.7/dist-packages/django/template/base.py", line 903, in render
    bit = self.render_node(node, context)
  File "/usr/local/lib/python2.7/dist-packages/django/template/debug.py", line 79, in render_node
    return node.render(context)
  File "/usr/local/lib/python2.7/dist-packages/django/template/loader_tags.py", line 65, in render
    result = block.nodelist.render(context)
  File "/usr/local/lib/python2.7/dist-packages/django/template/base.py", line 903, in render
    bit = self.render_node(node, context)
  File "/usr/local/lib/python2.7/dist-packages/django/template/debug.py", line 79, in render_node
    return node.render(context)
  File "/usr/local/lib/python2.7/dist-packages/django/template/base.py", line 1271, in render
    _dict = func(*resolved_args, **resolved_kwargs)
  File "/usr/local/lib/python2.7/dist-packages/django/contrib/admin/templatetags/admin_list.py", line 311, in result_list
    headers = list(result_headers(cl))
  File "/usr/local/lib/python2.7/dist-packages/django/contrib/admin/templatetags/admin_list.py", line 102, in result_headers
    return_attr=True
  File "/usr/local/lib/python2.7/dist-packages/django/contrib/admin/utils.py", line 337, in label_for_field
    raise AttributeError(message)
AttributeError: Unable to lookup 'was_published_recently' on Question or QuestionAdmin
2015-07-09 22:30:49,951 [WARNING] django.request: Not Found: /favicon.ico
2015-07-09 22:36:47,975 [WARNING] django.request: Not Found: /
2015-07-09 22:43:04,877 [ERROR] django.request: Internal Server Error: /
Traceback (most recent call last):
  File "/usr/local/lib/python2.7/dist-packages/django/core/handlers/base.py", line 119, in get_response
    resolver_match = resolver.resolve(request.path_info)
  File "/usr/local/lib/python2.7/dist-packages/django/core/urlresolvers.py", line 366, in resolve
    for pattern in self.url_patterns:
  File "/usr/local/lib/python2.7/dist-packages/django/core/urlresolvers.py", line 402, in url_patterns
    patterns = getattr(self.urlconf_module, "urlpatterns", self.urlconf_module)
  File "/usr/local/lib/python2.7/dist-packages/django/core/urlresolvers.py", line 396, in urlconf_module
    self._urlconf_module = import_module(self.urlconf_name)
  File "/usr/lib/python2.7/importlib/__init__.py", line 37, in import_module
    __import__(name)
  File "/home/george/djangoSite/djangoSite/urls.py", line 20, in <module>
    from django.views.generic.simple import direct_to_template
ImportError: No module named simple
2015-07-09 22:43:29,033 [ERROR] django.request: Internal Server Error: /admin/
Traceback (most recent call last):
  File "/usr/local/lib/python2.7/dist-packages/django/core/handlers/base.py", line 119, in get_response
    resolver_match = resolver.resolve(request.path_info)
  File "/usr/local/lib/python2.7/dist-packages/django/core/urlresolvers.py", line 366, in resolve
    for pattern in self.url_patterns:
  File "/usr/local/lib/python2.7/dist-packages/django/core/urlresolvers.py", line 402, in url_patterns
    patterns = getattr(self.urlconf_module, "urlpatterns", self.urlconf_module)
  File "/usr/local/lib/python2.7/dist-packages/django/core/urlresolvers.py", line 396, in urlconf_module
    self._urlconf_module = import_module(self.urlconf_name)
  File "/usr/lib/python2.7/importlib/__init__.py", line 37, in import_module
    __import__(name)
  File "/home/george/djangoSite/djangoSite/urls.py", line 20, in <module>
    from django.views.generic.simple import direct_to_template
ImportError: No module named simple
2015-07-09 22:46:39,733 [ERROR] django.request: Internal Server Error: /
Traceback (most recent call last):
  File "/usr/local/lib/python2.7/dist-packages/django/core/handlers/base.py", line 119, in get_response
    resolver_match = resolver.resolve(request.path_info)
  File "/usr/local/lib/python2.7/dist-packages/django/core/urlresolvers.py", line 366, in resolve
    for pattern in self.url_patterns:
  File "/usr/local/lib/python2.7/dist-packages/django/core/urlresolvers.py", line 402, in url_patterns
    patterns = getattr(self.urlconf_module, "urlpatterns", self.urlconf_module)
  File "/usr/local/lib/python2.7/dist-packages/django/core/urlresolvers.py", line 396, in urlconf_module
    self._urlconf_module = import_module(self.urlconf_name)
  File "/usr/lib/python2.7/importlib/__init__.py", line 37, in import_module
    __import__(name)
  File "/home/george/djangoSite/djangoSite/urls.py", line 20, in <module>
    from django.views.generic.simple import direct_to_template
ImportError: No module named simple
2015-07-09 22:46:41,527 [ERROR] django.request: Internal Server Error: /
Traceback (most recent call last):
  File "/usr/local/lib/python2.7/dist-packages/django/core/handlers/base.py", line 119, in get_response
    resolver_match = resolver.resolve(request.path_info)
  File "/usr/local/lib/python2.7/dist-packages/django/core/urlresolvers.py", line 366, in resolve
    for pattern in self.url_patterns:
  File "/usr/local/lib/python2.7/dist-packages/django/core/urlresolvers.py", line 402, in url_patterns
    patterns = getattr(self.urlconf_module, "urlpatterns", self.urlconf_module)
  File "/usr/local/lib/python2.7/dist-packages/django/core/urlresolvers.py", line 396, in urlconf_module
    self._urlconf_module = import_module(self.urlconf_name)
  File "/usr/lib/python2.7/importlib/__init__.py", line 37, in import_module
    __import__(name)
  File "/home/george/djangoSite/djangoSite/urls.py", line 20, in <module>
    from django.views.generic.simple import direct_to_template
ImportError: No module named simple
2015-07-09 22:47:43,459 [ERROR] django.request: Internal Server Error: /
Traceback (most recent call last):
  File "/usr/local/lib/python2.7/dist-packages/django/core/handlers/base.py", line 119, in get_response
    resolver_match = resolver.resolve(request.path_info)
  File "/usr/local/lib/python2.7/dist-packages/django/core/urlresolvers.py", line 366, in resolve
    for pattern in self.url_patterns:
  File "/usr/local/lib/python2.7/dist-packages/django/core/urlresolvers.py", line 402, in url_patterns
    patterns = getattr(self.urlconf_module, "urlpatterns", self.urlconf_module)
  File "/usr/local/lib/python2.7/dist-packages/django/core/urlresolvers.py", line 396, in urlconf_module
    self._urlconf_module = import_module(self.urlconf_name)
  File "/usr/lib/python2.7/importlib/__init__.py", line 37, in import_module
    __import__(name)
  File "/home/george/djangoSite/djangoSite/urls.py", line 20, in <module>
    from django.views.generic.simple import direct_to_template, simple
ImportError: No module named simple
2015-07-09 22:47:45,238 [ERROR] django.request: Internal Server Error: /
Traceback (most recent call last):
  File "/usr/local/lib/python2.7/dist-packages/django/core/handlers/base.py", line 119, in get_response
    resolver_match = resolver.resolve(request.path_info)
  File "/usr/local/lib/python2.7/dist-packages/django/core/urlresolvers.py", line 366, in resolve
    for pattern in self.url_patterns:
  File "/usr/local/lib/python2.7/dist-packages/django/core/urlresolvers.py", line 402, in url_patterns
    patterns = getattr(self.urlconf_module, "urlpatterns", self.urlconf_module)
  File "/usr/local/lib/python2.7/dist-packages/django/core/urlresolvers.py", line 396, in urlconf_module
    self._urlconf_module = import_module(self.urlconf_name)
  File "/usr/lib/python2.7/importlib/__init__.py", line 37, in import_module
    __import__(name)
  File "/home/george/djangoSite/djangoSite/urls.py", line 20, in <module>
    from django.views.generic.simple import direct_to_template, simple
ImportError: No module named simple
2015-07-09 22:47:46,165 [ERROR] django.request: Internal Server Error: /
Traceback (most recent call last):
  File "/usr/local/lib/python2.7/dist-packages/django/core/handlers/base.py", line 119, in get_response
    resolver_match = resolver.resolve(request.path_info)
  File "/usr/local/lib/python2.7/dist-packages/django/core/urlresolvers.py", line 366, in resolve
    for pattern in self.url_patterns:
  File "/usr/local/lib/python2.7/dist-packages/django/core/urlresolvers.py", line 402, in url_patterns
    patterns = getattr(self.urlconf_module, "urlpatterns", self.urlconf_module)
  File "/usr/local/lib/python2.7/dist-packages/django/core/urlresolvers.py", line 396, in urlconf_module
    self._urlconf_module = import_module(self.urlconf_name)
  File "/usr/lib/python2.7/importlib/__init__.py", line 37, in import_module
    __import__(name)
  File "/home/george/djangoSite/djangoSite/urls.py", line 20, in <module>
    from django.views.generic.simple import direct_to_template, simple
ImportError: No module named simple
2015-07-09 22:49:50,862 [ERROR] django.request: Internal Server Error: /
Traceback (most recent call last):
  File "/usr/local/lib/python2.7/dist-packages/django/core/handlers/base.py", line 119, in get_response
    resolver_match = resolver.resolve(request.path_info)
  File "/usr/local/lib/python2.7/dist-packages/django/core/urlresolvers.py", line 366, in resolve
    for pattern in self.url_patterns:
  File "/usr/local/lib/python2.7/dist-packages/django/core/urlresolvers.py", line 402, in url_patterns
    patterns = getattr(self.urlconf_module, "urlpatterns", self.urlconf_module)
  File "/usr/local/lib/python2.7/dist-packages/django/core/urlresolvers.py", line 396, in urlconf_module
    self._urlconf_module = import_module(self.urlconf_name)
  File "/usr/lib/python2.7/importlib/__init__.py", line 37, in import_module
    __import__(name)
  File "/home/george/djangoSite/djangoSite/urls.py", line 23, in <module>
    (r"^$", Template.as_view(template_name="index.html")),
NameError: name 'Template' is not defined
2015-07-09 23:15:19,114 [WARNING] django.request: Not Found: /favicon.ico
2015-07-10 01:44:03,479 [WARNING] django.request: Not Found: /favicon.ico
2015-07-10 02:08:31,525 [ERROR] django.request: Internal Server Error: /
Traceback (most recent call last):
  File "/usr/local/lib/python2.7/dist-packages/django/core/handlers/base.py", line 119, in get_response
    resolver_match = resolver.resolve(request.path_info)
  File "/usr/local/lib/python2.7/dist-packages/django/core/urlresolvers.py", line 366, in resolve
    for pattern in self.url_patterns:
  File "/usr/local/lib/python2.7/dist-packages/django/core/urlresolvers.py", line 402, in url_patterns
    patterns = getattr(self.urlconf_module, "urlpatterns", self.urlconf_module)
  File "/usr/local/lib/python2.7/dist-packages/django/core/urlresolvers.py", line 396, in urlconf_module
    self._urlconf_module = import_module(self.urlconf_name)
  File "/usr/lib/python2.7/importlib/__init__.py", line 37, in import_module
    __import__(name)
  File "/home/george/djangoSite/djangoSite/urls.py", line 24, in <module>
    url(r'^polls/', include('polls.urls')),
  File "/usr/local/lib/python2.7/dist-packages/django/conf/urls/__init__.py", line 33, in include
    urlconf_module = import_module(urlconf_module)
  File "/usr/lib/python2.7/importlib/__init__.py", line 37, in import_module
    __import__(name)
  File "/home/george/djangoSite/polls/urls.py", line 3, in <module>
    from . import views
  File "/home/george/djangoSite/polls/views.py", line 5
    return HttpResponse("Hello World, this is the polls index.")
         ^
IndentationError: expected an indented block
2015-07-10 02:08:32,241 [ERROR] django.request: Internal Server Error: /favicon.ico
Traceback (most recent call last):
  File "/usr/local/lib/python2.7/dist-packages/django/core/handlers/base.py", line 108, in get_response
    response = middleware_method(request)
  File "/usr/local/lib/python2.7/dist-packages/django/middleware/common.py", line 74, in process_request
    if (not urlresolvers.is_valid_path(request.path_info, urlconf) and
  File "/usr/local/lib/python2.7/dist-packages/django/core/urlresolvers.py", line 647, in is_valid_path
    resolve(path, urlconf)
  File "/usr/local/lib/python2.7/dist-packages/django/core/urlresolvers.py", line 522, in resolve
    return get_resolver(urlconf).resolve(path)
  File "/usr/local/lib/python2.7/dist-packages/django/core/urlresolvers.py", line 366, in resolve
    for pattern in self.url_patterns:
  File "/usr/local/lib/python2.7/dist-packages/django/core/urlresolvers.py", line 402, in url_patterns
    patterns = getattr(self.urlconf_module, "urlpatterns", self.urlconf_module)
  File "/usr/local/lib/python2.7/dist-packages/django/core/urlresolvers.py", line 396, in urlconf_module
    self._urlconf_module = import_module(self.urlconf_name)
  File "/usr/lib/python2.7/importlib/__init__.py", line 37, in import_module
    __import__(name)
  File "/home/george/djangoSite/djangoSite/urls.py", line 24, in <module>
    url(r'^polls/', include('polls.urls')),
  File "/usr/local/lib/python2.7/dist-packages/django/conf/urls/__init__.py", line 33, in include
    urlconf_module = import_module(urlconf_module)
  File "/usr/lib/python2.7/importlib/__init__.py", line 37, in import_module
    __import__(name)
  File "/home/george/djangoSite/polls/urls.py", line 3, in <module>
    from . import views
  File "/home/george/djangoSite/polls/views.py", line 5
    return HttpResponse("Hello World, this is the polls index.")
         ^
IndentationError: expected an indented block
2015-07-10 02:09:17,387 [WARNING] django.request: Not Found: /favicon.ico
2015-07-10 03:16:03,196 [WARNING] django.request: Not Found: /favicon.ico
2015-07-10 03:19:29,178 [ERROR] django.request: Internal Server Error: /polls/send
Traceback (most recent call last):
  File "/usr/local/lib/python2.7/dist-packages/django/core/handlers/base.py", line 132, in get_response
    response = wrapped_callback(request, *callback_args, **callback_kwargs)
  File "/home/george/djangoSite/polls/views.py", line 8, in send
    mylog.lg
NameError: global name 'mylog' is not defined
2015-07-10 03:31:44,140 [ERROR] django.request: Internal Server Error: /polls/send
Traceback (most recent call last):
  File "/usr/local/lib/python2.7/dist-packages/django/core/handlers/base.py", line 151, in get_response
    % (callback.__module__, view_name))
ValueError: The view polls.views.send didn't return an HttpResponse object. It returned None instead.
2015-07-10 03:56:13,016 [WARNING] django.request: Not Found: /testproxy.php
2015-07-10 05:04:58,056 [WARNING] django.request: Not Found: /CFIDE/administrator/
2015-07-10 14:58:21,449 [WARNING] django.request: Not Found: /favicon.ico
2015-07-10 17:41:47,594 [WARNING] django.request: Not Found: /favicon.ico
2015-07-10 18:04:32,766 [ERROR] django.request: Internal Server Error: /
Traceback (most recent call last):
  File "/usr/local/lib/python2.7/dist-packages/django/core/handlers/base.py", line 119, in get_response
    resolver_match = resolver.resolve(request.path_info)
  File "/usr/local/lib/python2.7/dist-packages/django/core/urlresolvers.py", line 366, in resolve
    for pattern in self.url_patterns:
  File "/usr/local/lib/python2.7/dist-packages/django/core/urlresolvers.py", line 402, in url_patterns
    patterns = getattr(self.urlconf_module, "urlpatterns", self.urlconf_module)
  File "/usr/local/lib/python2.7/dist-packages/django/core/urlresolvers.py", line 396, in urlconf_module
    self._urlconf_module = import_module(self.urlconf_name)
  File "/usr/lib/python2.7/importlib/__init__.py", line 37, in import_module
    __import__(name)
  File "/home/george/djangoSite/djangoSite/urls.py", line 24, in <module>
    url(r'^polls/', include('polls.urls')),
  File "/usr/local/lib/python2.7/dist-packages/django/conf/urls/__init__.py", line 33, in include
    urlconf_module = import_module(urlconf_module)
  File "/usr/lib/python2.7/importlib/__init__.py", line 37, in import_module
    __import__(name)
  File "/home/george/djangoSite/polls/urls.py", line 10
    url(r'(?P<question_id>[0-9]+)/vote/$', views.vote, name='vote')
      ^
SyntaxError: invalid syntax
2015-07-10 18:20:46,264 [WARNING] django.request: Not Found: /poop/polls/3/results/
2015-07-10 19:14:37,572 [ERROR] django.request: Internal Server Error: /polls/
Traceback (most recent call last):
  File "/usr/local/lib/python2.7/dist-packages/django/core/handlers/base.py", line 132, in get_response
    response = wrapped_callback(request, *callback_args, **callback_kwargs)
  File "/home/george/djangoSite/polls/views.py", line 11, in index
    return render(request, 'polls/index', context)
  File "/usr/local/lib/python2.7/dist-packages/django/shortcuts.py", line 67, in render
    template_name, context, request=request, using=using)
  File "/usr/local/lib/python2.7/dist-packages/django/template/loader.py", line 98, in render_to_string
    template = get_template(template_name, using=using)
  File "/usr/local/lib/python2.7/dist-packages/django/template/loader.py", line 46, in get_template
    raise TemplateDoesNotExist(template_name)
TemplateDoesNotExist: polls/index
2015-07-10 19:14:59,924 [ERROR] django.request: Internal Server Error: /polls/
Traceback (most recent call last):
  File "/usr/local/lib/python2.7/dist-packages/django/core/handlers/base.py", line 132, in get_response
    response = wrapped_callback(request, *callback_args, **callback_kwargs)
  File "/home/george/djangoSite/polls/views.py", line 11, in index
    return render(request, 'polls/index.html', context)
  File "/usr/local/lib/python2.7/dist-packages/django/shortcuts.py", line 67, in render
    template_name, context, request=request, using=using)
  File "/usr/local/lib/python2.7/dist-packages/django/template/loader.py", line 98, in render_to_string
    template = get_template(template_name, using=using)
  File "/usr/local/lib/python2.7/dist-packages/django/template/loader.py", line 46, in get_template
    raise TemplateDoesNotExist(template_name)
TemplateDoesNotExist: polls/index
2015-07-10 19:15:01,068 [ERROR] django.request: Internal Server Error: /polls/
Traceback (most recent call last):
  File "/usr/local/lib/python2.7/dist-packages/django/core/handlers/base.py", line 132, in get_response
    response = wrapped_callback(request, *callback_args, **callback_kwargs)
  File "/home/george/djangoSite/polls/views.py", line 11, in index
    return render(request, 'polls/index.html', context)
  File "/usr/local/lib/python2.7/dist-packages/django/shortcuts.py", line 67, in render
    template_name, context, request=request, using=using)
  File "/usr/local/lib/python2.7/dist-packages/django/template/loader.py", line 98, in render_to_string
    template = get_template(template_name, using=using)
  File "/usr/local/lib/python2.7/dist-packages/django/template/loader.py", line 46, in get_template
    raise TemplateDoesNotExist(template_name)
TemplateDoesNotExist: polls/index
2015-07-10 19:15:03,192 [ERROR] django.request: Internal Server Error: /polls/
Traceback (most recent call last):
  File "/usr/local/lib/python2.7/dist-packages/django/core/handlers/base.py", line 132, in get_response
    response = wrapped_callback(request, *callback_args, **callback_kwargs)
  File "/home/george/djangoSite/polls/views.py", line 11, in index
    return render(request, 'polls/index.html', context)
  File "/usr/local/lib/python2.7/dist-packages/django/shortcuts.py", line 67, in render
    template_name, context, request=request, using=using)
  File "/usr/local/lib/python2.7/dist-packages/django/template/loader.py", line 98, in render_to_string
    template = get_template(template_name, using=using)
  File "/usr/local/lib/python2.7/dist-packages/django/template/loader.py", line 46, in get_template
    raise TemplateDoesNotExist(template_name)
TemplateDoesNotExist: polls/index
2015-07-10 19:22:24,050 [WARNING] django.request: Not Found: /polls/5/
2015-07-10 19:25:09,229 [WARNING] django.request: Not Found: /polls/5/
2015-07-10 19:25:10,431 [WARNING] django.request: Not Found: /polls/5/
2015-07-10 19:25:11,309 [WARNING] django.request: Not Found: /polls/5/
2015-07-10 19:29:11,194 [WARNING] django.request: Not Found: /polls/5/
2015-07-10 19:37:16,172 [ERROR] django.request: Internal Server Error: /polls/
Traceback (most recent call last):
  File "/usr/local/lib/python2.7/dist-packages/django/core/handlers/base.py", line 119, in get_response
    resolver_match = resolver.resolve(request.path_info)
  File "/usr/local/lib/python2.7/dist-packages/django/core/urlresolvers.py", line 366, in resolve
    for pattern in self.url_patterns:
  File "/usr/local/lib/python2.7/dist-packages/django/core/urlresolvers.py", line 402, in url_patterns
    patterns = getattr(self.urlconf_module, "urlpatterns", self.urlconf_module)
  File "/usr/local/lib/python2.7/dist-packages/django/core/urlresolvers.py", line 396, in urlconf_module
    self._urlconf_module = import_module(self.urlconf_name)
  File "/usr/lib/python2.7/importlib/__init__.py", line 37, in import_module
    __import__(name)
  File "/home/george/djangoSite/djangoSite/urls.py", line 24, in <module>
    url(r'^polls/', include('polls.urls'), namespace='polls'),
TypeError: url() got an unexpected keyword argument 'namespace'
2015-07-11 00:36:21,202 [ERROR] django.request: Internal Server Error: /polls/2/vote/
Traceback (most recent call last):
  File "/usr/local/lib/python2.7/dist-packages/django/core/handlers/base.py", line 132, in get_response
    response = wrapped_callback(request, *callback_args, **callback_kwargs)
  File "/home/george/djangoSite/polls/views.py", line 43, in vote
    return HttpResponseRedirect(reverse('polls:results', args=(p.id,)))
NameError: global name 'reverse' is not defined
2015-07-11 00:37:08,227 [ERROR] django.request: Internal Server Error: /polls/2/vote/
Traceback (most recent call last):
  File "/usr/local/lib/python2.7/dist-packages/django/core/handlers/base.py", line 132, in get_response
    response = wrapped_callback(request, *callback_args, **callback_kwargs)
  File "/home/george/djangoSite/polls/views.py", line 43, in vote
    # user hits the Back button.
NameError: global name 'reverse' is not defined
2015-07-11 01:14:45,649 [WARNING] django.request: Not Found: /favicon.ico
2015-07-11 02:02:02,025 [WARNING] django.request: Not Found: /favicon.ico
2015-07-11 06:36:56,906 [WARNING] django.request: Not Found: /etc/lib/pChart2/examples/index.php
2015-07-11 12:53:31,796 [WARNING] django.request: Forbidden (CSRF cookie not set.): /
2015-07-11 17:52:23,269 [WARNING] django.request: Not Found: /favicon.ico
2015-07-11 21:28:24,911 [WARNING] django.request: Not Found: /favicon.ico
2015-07-11 21:36:39,772 [WARNING] django.request: Not Found: /favicon.ico
2015-07-11 21:41:53,251 [WARNING] django.request: Not Found: /favicon.ico
2015-07-11 22:05:19,916 [WARNING] django.request: Not Found: /favicon.ico
2015-07-11 23:18:27,243 [WARNING] django.request: Not Found: /manager/html
2015-07-12 01:32:12,392 [WARNING] django.request: Not Found: /etc/lib/pChart2/examples/index.php
2015-07-12 01:45:00,641 [WARNING] django.request: Not Found: /favicon.ico
2015-07-12 01:58:47,765 [WARNING] django.request: Not Found: /favicon.ico
2015-07-12 02:41:20,393 [WARNING] django.request: Not Found: /polls/2/
2015-07-12 02:46:10,837 [WARNING] django.request: Not Found: /favicon.ico
2015-07-12 12:57:03,090 [WARNING] django.request: Not Found: /favicon.ico
2015-07-12 13:08:55,826 [WARNING] django.request: Not Found: /favicon.ico
2015-07-12 13:29:31,153 [ERROR] django.request: Internal Server Error: /polls/
Traceback (most recent call last):
  File "/usr/local/lib/python2.7/dist-packages/django/core/handlers/base.py", line 119, in get_response
    resolver_match = resolver.resolve(request.path_info)
  File "/usr/local/lib/python2.7/dist-packages/django/core/urlresolvers.py", line 366, in resolve
    for pattern in self.url_patterns:
  File "/usr/local/lib/python2.7/dist-packages/django/core/urlresolvers.py", line 402, in url_patterns
    patterns = getattr(self.urlconf_module, "urlpatterns", self.urlconf_module)
  File "/usr/local/lib/python2.7/dist-packages/django/core/urlresolvers.py", line 396, in urlconf_module
    self._urlconf_module = import_module(self.urlconf_name)
  File "/usr/lib/python2.7/importlib/__init__.py", line 37, in import_module
    __import__(name)
  File "/home/george/djangoSite/djangoSite/urls.py", line 24, in <module>
    url(r'^polls/', include('polls.urls', namespace="polls")),
  File "/usr/local/lib/python2.7/dist-packages/django/conf/urls/__init__.py", line 33, in include
    urlconf_module = import_module(urlconf_module)
  File "/usr/lib/python2.7/importlib/__init__.py", line 37, in import_module
    __import__(name)
  File "/home/george/djangoSite/polls/urls.py", line 3, in <module>
    from . import views
  File "/home/george/djangoSite/polls/views.py", line 52
    p.ip_already_voted.append(get_client_ip(request)
    ^
IndentationError: unexpected indent
2015-07-12 13:30:14,913 [ERROR] django.request: Internal Server Error: /polls/
Traceback (most recent call last):
  File "/usr/local/lib/python2.7/dist-packages/django/core/handlers/base.py", line 119, in get_response
    resolver_match = resolver.resolve(request.path_info)
  File "/usr/local/lib/python2.7/dist-packages/django/core/urlresolvers.py", line 366, in resolve
    for pattern in self.url_patterns:
  File "/usr/local/lib/python2.7/dist-packages/django/core/urlresolvers.py", line 402, in url_patterns
    patterns = getattr(self.urlconf_module, "urlpatterns", self.urlconf_module)
  File "/usr/local/lib/python2.7/dist-packages/django/core/urlresolvers.py", line 396, in urlconf_module
    self._urlconf_module = import_module(self.urlconf_name)
  File "/usr/lib/python2.7/importlib/__init__.py", line 37, in import_module
    __import__(name)
  File "/home/george/djangoSite/djangoSite/urls.py", line 24, in <module>
    url(r'^polls/', include('polls.urls', namespace="polls")),
  File "/usr/local/lib/python2.7/dist-packages/django/conf/urls/__init__.py", line 33, in include
    urlconf_module = import_module(urlconf_module)
  File "/usr/lib/python2.7/importlib/__init__.py", line 37, in import_module
    __import__(name)
  File "/home/george/djangoSite/polls/urls.py", line 3, in <module>
    from . import views
  File "/home/george/djangoSite/polls/views.py", line 53
    selected_choice.save()
                  ^
SyntaxError: invalid syntax
2015-07-12 13:34:15,730 [ERROR] django.request: Internal Server Error: /
Traceback (most recent call last):
  File "/usr/local/lib/python2.7/dist-packages/django/core/handlers/base.py", line 119, in get_response
    resolver_match = resolver.resolve(request.path_info)
  File "/usr/local/lib/python2.7/dist-packages/django/core/urlresolvers.py", line 366, in resolve
    for pattern in self.url_patterns:
  File "/usr/local/lib/python2.7/dist-packages/django/core/urlresolvers.py", line 402, in url_patterns
    patterns = getattr(self.urlconf_module, "urlpatterns", self.urlconf_module)
  File "/usr/local/lib/python2.7/dist-packages/django/core/urlresolvers.py", line 396, in urlconf_module
    self._urlconf_module = import_module(self.urlconf_name)
  File "/usr/lib/python2.7/importlib/__init__.py", line 37, in import_module
    __import__(name)
  File "/home/george/djangoSite/djangoSite/urls.py", line 24, in <module>
    url(r'^polls/', include('polls.urls', namespace="polls")),
  File "/usr/local/lib/python2.7/dist-packages/django/conf/urls/__init__.py", line 33, in include
    urlconf_module = import_module(urlconf_module)
  File "/usr/lib/python2.7/importlib/__init__.py", line 37, in import_module
    __import__(name)
  File "/home/george/djangoSite/polls/urls.py", line 3, in <module>
    from . import views
  File "/home/george/djangoSite/polls/views.py", line 52
    selected_choice.votes += 1
                  ^
IndentationError: expected an indented block
2015-07-12 13:35:06,922 [ERROR] django.request: Internal Server Error: /
Traceback (most recent call last):
  File "/usr/local/lib/python2.7/dist-packages/django/core/handlers/base.py", line 119, in get_response
    resolver_match = resolver.resolve(request.path_info)
  File "/usr/local/lib/python2.7/dist-packages/django/core/urlresolvers.py", line 366, in resolve
    for pattern in self.url_patterns:
  File "/usr/local/lib/python2.7/dist-packages/django/core/urlresolvers.py", line 402, in url_patterns
    patterns = getattr(self.urlconf_module, "urlpatterns", self.urlconf_module)
  File "/usr/local/lib/python2.7/dist-packages/django/core/urlresolvers.py", line 396, in urlconf_module
    self._urlconf_module = import_module(self.urlconf_name)
  File "/usr/lib/python2.7/importlib/__init__.py", line 37, in import_module
    __import__(name)
  File "/home/george/djangoSite/djangoSite/urls.py", line 24, in <module>
    url(r'^polls/', include('polls.urls', namespace="polls")),
  File "/usr/local/lib/python2.7/dist-packages/django/conf/urls/__init__.py", line 33, in include
    urlconf_module = import_module(urlconf_module)
  File "/usr/lib/python2.7/importlib/__init__.py", line 37, in import_module
    __import__(name)
  File "/home/george/djangoSite/polls/urls.py", line 3, in <module>
    from . import views
  File "/home/george/djangoSite/polls/views.py", line 52
    selected_choice.votes += 1
                             ^
IndentationError: unindent does not match any outer indentation level
2015-07-12 13:35:45,189 [ERROR] django.request: Internal Server Error: /
Traceback (most recent call last):
  File "/usr/local/lib/python2.7/dist-packages/django/core/handlers/base.py", line 119, in get_response
    resolver_match = resolver.resolve(request.path_info)
  File "/usr/local/lib/python2.7/dist-packages/django/core/urlresolvers.py", line 366, in resolve
    for pattern in self.url_patterns:
  File "/usr/local/lib/python2.7/dist-packages/django/core/urlresolvers.py", line 402, in url_patterns
    patterns = getattr(self.urlconf_module, "urlpatterns", self.urlconf_module)
  File "/usr/local/lib/python2.7/dist-packages/django/core/urlresolvers.py", line 396, in urlconf_module
    self._urlconf_module = import_module(self.urlconf_name)
  File "/usr/lib/python2.7/importlib/__init__.py", line 37, in import_module
    __import__(name)
  File "/home/george/djangoSite/djangoSite/urls.py", line 24, in <module>
    url(r'^polls/', include('polls.urls', namespace="polls")),
  File "/usr/local/lib/python2.7/dist-packages/django/conf/urls/__init__.py", line 33, in include
    urlconf_module = import_module(urlconf_module)
  File "/usr/lib/python2.7/importlib/__init__.py", line 37, in import_module
    __import__(name)
  File "/home/george/djangoSite/polls/urls.py", line 3, in <module>
    from . import views
  File "/home/george/djangoSite/polls/views.py", line 52
    selected_choice.votes += 1
                  ^
IndentationError: expected an indented block
2015-07-12 13:37:07,633 [ERROR] django.request: Internal Server Error: /polls/2/vote/
Traceback (most recent call last):
  File "/usr/local/lib/python2.7/dist-packages/django/core/handlers/base.py", line 132, in get_response
    response = wrapped_callback(request, *callback_args, **callback_kwargs)
  File "/home/george/djangoSite/polls/views.py", line 51, in vote
    if not(p.ip_already_voted.contains(get_clinet_ip(request))):
AttributeError: 'list' object has no attribute 'contains'
2015-07-12 13:40:14,252 [ERROR] django.request: Internal Server Error: /polls/2/results/
Traceback (most recent call last):
  File "/usr/local/lib/python2.7/dist-packages/django/core/handlers/base.py", line 119, in get_response
    resolver_match = resolver.resolve(request.path_info)
  File "/usr/local/lib/python2.7/dist-packages/django/core/urlresolvers.py", line 366, in resolve
    for pattern in self.url_patterns:
  File "/usr/local/lib/python2.7/dist-packages/django/core/urlresolvers.py", line 402, in url_patterns
    patterns = getattr(self.urlconf_module, "urlpatterns", self.urlconf_module)
  File "/usr/local/lib/python2.7/dist-packages/django/core/urlresolvers.py", line 396, in urlconf_module
    self._urlconf_module = import_module(self.urlconf_name)
  File "/usr/lib/python2.7/importlib/__init__.py", line 37, in import_module
    __import__(name)
  File "/home/george/djangoSite/djangoSite/urls.py", line 24, in <module>
    url(r'^polls/', include('polls.urls', namespace="polls")),
  File "/usr/local/lib/python2.7/dist-packages/django/conf/urls/__init__.py", line 33, in include
    urlconf_module = import_module(urlconf_module)
  File "/usr/lib/python2.7/importlib/__init__.py", line 37, in import_module
    __import__(name)
  File "/home/george/djangoSite/polls/urls.py", line 3, in <module>
    from . import views
  File "/home/george/djangoSite/polls/views.py", line 58
    return HttpResponseRedirect(reverse('polls:results', args=(p.id,)))
                                                                      ^
IndentationError: unindent does not match any outer indentation level
2015-07-12 13:46:21,905 [ERROR] django.request: Internal Server Error: /polls/
Traceback (most recent call last):
  File "/usr/local/lib/python2.7/dist-packages/django/core/handlers/base.py", line 119, in get_response
    resolver_match = resolver.resolve(request.path_info)
  File "/usr/local/lib/python2.7/dist-packages/django/core/urlresolvers.py", line 366, in resolve
    for pattern in self.url_patterns:
  File "/usr/local/lib/python2.7/dist-packages/django/core/urlresolvers.py", line 402, in url_patterns
    patterns = getattr(self.urlconf_module, "urlpatterns", self.urlconf_module)
  File "/usr/local/lib/python2.7/dist-packages/django/core/urlresolvers.py", line 396, in urlconf_module
    self._urlconf_module = import_module(self.urlconf_name)
  File "/usr/lib/python2.7/importlib/__init__.py", line 37, in import_module
    __import__(name)
  File "/home/george/djangoSite/djangoSite/urls.py", line 24, in <module>
    url(r'^polls/', include('polls.urls', namespace="polls")),
  File "/usr/local/lib/python2.7/dist-packages/django/conf/urls/__init__.py", line 33, in include
    urlconf_module = import_module(urlconf_module)
  File "/usr/lib/python2.7/importlib/__init__.py", line 37, in import_module
    __import__(name)
  File "/home/george/djangoSite/polls/urls.py", line 3, in <module>
    from . import views
  File "/home/george/djangoSite/polls/views.py", line 55
    p.save()
    ^
IndentationError: unexpected indent
2015-07-12 13:53:54,800 [ERROR] django.request: Internal Server Error: /polls/2/
Traceback (most recent call last):
  File "/usr/local/lib/python2.7/dist-packages/django/core/handlers/base.py", line 119, in get_response
    resolver_match = resolver.resolve(request.path_info)
  File "/usr/local/lib/python2.7/dist-packages/django/core/urlresolvers.py", line 366, in resolve
    for pattern in self.url_patterns:
  File "/usr/local/lib/python2.7/dist-packages/django/core/urlresolvers.py", line 402, in url_patterns
    patterns = getattr(self.urlconf_module, "urlpatterns", self.urlconf_module)
  File "/usr/local/lib/python2.7/dist-packages/django/core/urlresolvers.py", line 396, in urlconf_module
    self._urlconf_module = import_module(self.urlconf_name)
  File "/usr/lib/python2.7/importlib/__init__.py", line 37, in import_module
    __import__(name)
  File "/home/george/djangoSite/djangoSite/urls.py", line 24, in <module>
    url(r'^polls/', include('polls.urls', namespace="polls")),
  File "/usr/local/lib/python2.7/dist-packages/django/conf/urls/__init__.py", line 33, in include
    urlconf_module = import_module(urlconf_module)
  File "/usr/lib/python2.7/importlib/__init__.py", line 37, in import_module
    __import__(name)
  File "/home/george/djangoSite/polls/urls.py", line 3, in <module>
    from . import views
  File "/home/george/djangoSite/polls/views.py", line 57
    logger.error(p.ip_already_voted)
    ^
IndentationError: unexpected indent
2015-07-12 14:04:48,285 [ERROR] django.request: Internal Server Error: /polls
Traceback (most recent call last):
  File "/usr/local/lib/python2.7/dist-packages/django/core/handlers/base.py", line 108, in get_response
    response = middleware_method(request)
  File "/usr/local/lib/python2.7/dist-packages/django/middleware/common.py", line 74, in process_request
    if (not urlresolvers.is_valid_path(request.path_info, urlconf) and
  File "/usr/local/lib/python2.7/dist-packages/django/core/urlresolvers.py", line 647, in is_valid_path
    resolve(path, urlconf)
  File "/usr/local/lib/python2.7/dist-packages/django/core/urlresolvers.py", line 522, in resolve
    return get_resolver(urlconf).resolve(path)
  File "/usr/local/lib/python2.7/dist-packages/django/core/urlresolvers.py", line 366, in resolve
    for pattern in self.url_patterns:
  File "/usr/local/lib/python2.7/dist-packages/django/core/urlresolvers.py", line 402, in url_patterns
    patterns = getattr(self.urlconf_module, "urlpatterns", self.urlconf_module)
  File "/usr/local/lib/python2.7/dist-packages/django/core/urlresolvers.py", line 396, in urlconf_module
    self._urlconf_module = import_module(self.urlconf_name)
  File "/usr/lib/python2.7/importlib/__init__.py", line 37, in import_module
    __import__(name)
  File "/home/george/djangoSite/djangoSite/urls.py", line 24, in <module>
    url(r'^polls/', include('polls.urls', namespace="polls")),
  File "/usr/local/lib/python2.7/dist-packages/django/conf/urls/__init__.py", line 33, in include
    urlconf_module = import_module(urlconf_module)
  File "/usr/lib/python2.7/importlib/__init__.py", line 37, in import_module
    __import__(name)
  File "/home/george/djangoSite/polls/urls.py", line 3, in <module>
    from . import views
  File "/home/george/djangoSite/polls/views.py", line 59
    else:
        ^
IndentationError: unindent does not match any outer indentation level
2015-07-12 16:24:59,674 [WARNING] django.request: Not Found: /favicon.ico
2015-07-12 19:41:19,036 [WARNING] django.request: Not Found: /favicon.ico
2015-07-12 19:51:20,131 [ERROR] django.request: Internal Server Error: /polls/2/vote/
Traceback (most recent call last):
  File "/usr/local/lib/python2.7/dist-packages/django/core/handlers/base.py", line 132, in get_response
    response = wrapped_callback(request, *callback_args, **callback_kwargs)
  File "/home/george/djangoSite/polls/views.py", line 52, in vote
    if not(get_client_ip(request) in p.ip_already_voted):
AttributeError: 'Question' object has no attribute 'ip_already_voted'
2015-07-12 20:03:21,457 [ERROR] django.request: Internal Server Error: /polls/2/vote/
Traceback (most recent call last):
  File "/usr/local/lib/python2.7/dist-packages/django/core/handlers/base.py", line 132, in get_response
    response = wrapped_callback(request, *callback_args, **callback_kwargs)
  File "/home/george/djangoSite/polls/views.py", line 52, in vote
    if p.ipAlreadyVoted_set.filter(ip=get_client_ip(request)) == []:
AttributeError: 'Question' object has no attribute 'ipAlreadyVoted_set'
2015-07-12 20:09:11,663 [ERROR] django.request: Internal Server Error: /polls/2/vote/
Traceback (most recent call last):
  File "/usr/local/lib/python2.7/dist-packages/django/core/handlers/base.py", line 132, in get_response
    response = wrapped_callback(request, *callback_args, **callback_kwargs)
  File "/home/george/djangoSite/polls/views.py", line 52, in vote
    logger.error(p.ipalreadyvoted_set.filter(ip=get_client_ip(request)).length())
AttributeError: 'QuerySet' object has no attribute 'length'
2015-07-13 00:43:43,061 [WARNING] django.request: Not Found: /cgi-bin/mft/wireless_mft
2015-07-13 00:43:55,109 [WARNING] django.request: Not Found: /maker/snwrite.cgi
2015-07-13 00:44:06,613 [WARNING] django.request: Not Found: /cgi_test.cgi
2015-07-13 04:36:55,326 [WARNING] django.request: Not Found: /testproxy.php
2015-07-13 07:33:40,296 [WARNING] django.request: Not Found: /Ringing.at.your.dorbell!
2015-07-13 07:33:42,376 [WARNING] django.request: Not Found: /Diagnostics.asp
2015-07-13 12:51:32,058 [WARNING] django.request: Not Found: /favicon.ico
2015-07-13 17:22:17,298 [WARNING] django.request: Not Found: /favicon.ico
2015-07-13 17:45:14,602 [ERROR] django.request: Internal Server Error: /polls/1/
Traceback (most recent call last):
  File "/usr/local/lib/python2.7/dist-packages/django/core/handlers/base.py", line 164, in get_response
    response = response.render()
  File "/usr/local/lib/python2.7/dist-packages/django/template/response.py", line 158, in render
    self.content = self.rendered_content
  File "/usr/local/lib/python2.7/dist-packages/django/template/response.py", line 135, in rendered_content
    content = template.render(context, self._request)
  File "/usr/local/lib/python2.7/dist-packages/django/template/backends/django.py", line 74, in render
    return self.template.render(context)
  File "/usr/local/lib/python2.7/dist-packages/django/template/base.py", line 209, in render
    return self._render(context)
  File "/usr/local/lib/python2.7/dist-packages/django/template/base.py", line 201, in _render
    return self.nodelist.render(context)
  File "/usr/local/lib/python2.7/dist-packages/django/template/base.py", line 903, in render
    bit = self.render_node(node, context)
  File "/usr/local/lib/python2.7/dist-packages/django/template/debug.py", line 79, in render_node
    return node.render(context)
  File "/usr/local/lib/python2.7/dist-packages/django/template/defaulttags.py", line 507, in render
    six.reraise(*exc_info)
  File "/usr/local/lib/python2.7/dist-packages/django/template/defaulttags.py", line 493, in render
    url = reverse(view_name, args=args, kwargs=kwargs, current_app=current_app)
  File "/usr/local/lib/python2.7/dist-packages/django/core/urlresolvers.py", line 579, in reverse
    return force_text(iri_to_uri(resolver._reverse_with_prefix(view, prefix, *args, **kwargs)))
  File "/usr/local/lib/python2.7/dist-packages/django/core/urlresolvers.py", line 496, in _reverse_with_prefix
    (lookup_view_s, args, kwargs, len(patterns), patterns))
NoReverseMatch: Reverse for 'addChoice' with arguments '(1L,)' and keyword arguments '{}' not found. 0 pattern(s) tried: []
2015-07-13 17:46:09,975 [ERROR] django.request: Internal Server Error: /polls/1/
Traceback (most recent call last):
  File "/usr/local/lib/python2.7/dist-packages/django/core/handlers/base.py", line 164, in get_response
    response = response.render()
  File "/usr/local/lib/python2.7/dist-packages/django/template/response.py", line 158, in render
    self.content = self.rendered_content
  File "/usr/local/lib/python2.7/dist-packages/django/template/response.py", line 135, in rendered_content
    content = template.render(context, self._request)
  File "/usr/local/lib/python2.7/dist-packages/django/template/backends/django.py", line 74, in render
    return self.template.render(context)
  File "/usr/local/lib/python2.7/dist-packages/django/template/base.py", line 209, in render
    return self._render(context)
  File "/usr/local/lib/python2.7/dist-packages/django/template/base.py", line 201, in _render
    return self.nodelist.render(context)
  File "/usr/local/lib/python2.7/dist-packages/django/template/base.py", line 903, in render
    bit = self.render_node(node, context)
  File "/usr/local/lib/python2.7/dist-packages/django/template/debug.py", line 79, in render_node
    return node.render(context)
  File "/usr/local/lib/python2.7/dist-packages/django/template/defaulttags.py", line 507, in render
    six.reraise(*exc_info)
  File "/usr/local/lib/python2.7/dist-packages/django/template/defaulttags.py", line 493, in render
    url = reverse(view_name, args=args, kwargs=kwargs, current_app=current_app)
  File "/usr/local/lib/python2.7/dist-packages/django/core/urlresolvers.py", line 579, in reverse
    return force_text(iri_to_uri(resolver._reverse_with_prefix(view, prefix, *args, **kwargs)))
  File "/usr/local/lib/python2.7/dist-packages/django/core/urlresolvers.py", line 496, in _reverse_with_prefix
    (lookup_view_s, args, kwargs, len(patterns), patterns))
NoReverseMatch: Reverse for 'addChoice' with arguments '(1L,)' and keyword arguments '{}' not found. 0 pattern(s) tried: []
2015-07-13 17:46:11,002 [ERROR] django.request: Internal Server Error: /polls/1/
Traceback (most recent call last):
  File "/usr/local/lib/python2.7/dist-packages/django/core/handlers/base.py", line 164, in get_response
    response = response.render()
  File "/usr/local/lib/python2.7/dist-packages/django/template/response.py", line 158, in render
    self.content = self.rendered_content
  File "/usr/local/lib/python2.7/dist-packages/django/template/response.py", line 135, in rendered_content
    content = template.render(context, self._request)
  File "/usr/local/lib/python2.7/dist-packages/django/template/backends/django.py", line 74, in render
    return self.template.render(context)
  File "/usr/local/lib/python2.7/dist-packages/django/template/base.py", line 209, in render
    return self._render(context)
  File "/usr/local/lib/python2.7/dist-packages/django/template/base.py", line 201, in _render
    return self.nodelist.render(context)
  File "/usr/local/lib/python2.7/dist-packages/django/template/base.py", line 903, in render
    bit = self.render_node(node, context)
  File "/usr/local/lib/python2.7/dist-packages/django/template/debug.py", line 79, in render_node
    return node.render(context)
  File "/usr/local/lib/python2.7/dist-packages/django/template/defaulttags.py", line 507, in render
    six.reraise(*exc_info)
  File "/usr/local/lib/python2.7/dist-packages/django/template/defaulttags.py", line 493, in render
    url = reverse(view_name, args=args, kwargs=kwargs, current_app=current_app)
  File "/usr/local/lib/python2.7/dist-packages/django/core/urlresolvers.py", line 579, in reverse
    return force_text(iri_to_uri(resolver._reverse_with_prefix(view, prefix, *args, **kwargs)))
  File "/usr/local/lib/python2.7/dist-packages/django/core/urlresolvers.py", line 496, in _reverse_with_prefix
    (lookup_view_s, args, kwargs, len(patterns), patterns))
NoReverseMatch: Reverse for 'addChoice' with arguments '(1L,)' and keyword arguments '{}' not found. 0 pattern(s) tried: []
2015-07-13 17:46:56,582 [ERROR] django.request: Internal Server Error: /polls/2/
Traceback (most recent call last):
  File "/usr/local/lib/python2.7/dist-packages/django/core/handlers/base.py", line 164, in get_response
    response = response.render()
  File "/usr/local/lib/python2.7/dist-packages/django/template/response.py", line 158, in render
    self.content = self.rendered_content
  File "/usr/local/lib/python2.7/dist-packages/django/template/response.py", line 135, in rendered_content
    content = template.render(context, self._request)
  File "/usr/local/lib/python2.7/dist-packages/django/template/backends/django.py", line 74, in render
    return self.template.render(context)
  File "/usr/local/lib/python2.7/dist-packages/django/template/base.py", line 209, in render
    return self._render(context)
  File "/usr/local/lib/python2.7/dist-packages/django/template/base.py", line 201, in _render
    return self.nodelist.render(context)
  File "/usr/local/lib/python2.7/dist-packages/django/template/base.py", line 903, in render
    bit = self.render_node(node, context)
  File "/usr/local/lib/python2.7/dist-packages/django/template/debug.py", line 79, in render_node
    return node.render(context)
  File "/usr/local/lib/python2.7/dist-packages/django/template/defaulttags.py", line 507, in render
    six.reraise(*exc_info)
  File "/usr/local/lib/python2.7/dist-packages/django/template/defaulttags.py", line 493, in render
    url = reverse(view_name, args=args, kwargs=kwargs, current_app=current_app)
  File "/usr/local/lib/python2.7/dist-packages/django/core/urlresolvers.py", line 579, in reverse
    return force_text(iri_to_uri(resolver._reverse_with_prefix(view, prefix, *args, **kwargs)))
  File "/usr/local/lib/python2.7/dist-packages/django/core/urlresolvers.py", line 496, in _reverse_with_prefix
    (lookup_view_s, args, kwargs, len(patterns), patterns))
NoReverseMatch: Reverse for 'addChoice' with arguments '(2L,)' and keyword arguments '{}' not found. 0 pattern(s) tried: []
2015-07-13 17:49:49,623 [ERROR] django.request: Internal Server Error: /polls/2/
Traceback (most recent call last):
  File "/usr/local/lib/python2.7/dist-packages/django/core/handlers/base.py", line 164, in get_response
    response = response.render()
  File "/usr/local/lib/python2.7/dist-packages/django/template/response.py", line 158, in render
    self.content = self.rendered_content
  File "/usr/local/lib/python2.7/dist-packages/django/template/response.py", line 135, in rendered_content
    content = template.render(context, self._request)
  File "/usr/local/lib/python2.7/dist-packages/django/template/backends/django.py", line 74, in render
    return self.template.render(context)
  File "/usr/local/lib/python2.7/dist-packages/django/template/base.py", line 209, in render
    return self._render(context)
  File "/usr/local/lib/python2.7/dist-packages/django/template/base.py", line 201, in _render
    return self.nodelist.render(context)
  File "/usr/local/lib/python2.7/dist-packages/django/template/base.py", line 903, in render
    bit = self.render_node(node, context)
  File "/usr/local/lib/python2.7/dist-packages/django/template/debug.py", line 79, in render_node
    return node.render(context)
  File "/usr/local/lib/python2.7/dist-packages/django/template/defaulttags.py", line 507, in render
    six.reraise(*exc_info)
  File "/usr/local/lib/python2.7/dist-packages/django/template/defaulttags.py", line 493, in render
    url = reverse(view_name, args=args, kwargs=kwargs, current_app=current_app)
  File "/usr/local/lib/python2.7/dist-packages/django/core/urlresolvers.py", line 579, in reverse
    return force_text(iri_to_uri(resolver._reverse_with_prefix(view, prefix, *args, **kwargs)))
  File "/usr/local/lib/python2.7/dist-packages/django/core/urlresolvers.py", line 496, in _reverse_with_prefix
    (lookup_view_s, args, kwargs, len(patterns), patterns))
NoReverseMatch: Reverse for 'addChoice' with arguments '(2L,)' and keyword arguments '{}' not found. 0 pattern(s) tried: []
2015-07-13 17:49:50,827 [ERROR] django.request: Internal Server Error: /polls/2/
Traceback (most recent call last):
  File "/usr/local/lib/python2.7/dist-packages/django/core/handlers/base.py", line 164, in get_response
    response = response.render()
  File "/usr/local/lib/python2.7/dist-packages/django/template/response.py", line 158, in render
    self.content = self.rendered_content
  File "/usr/local/lib/python2.7/dist-packages/django/template/response.py", line 135, in rendered_content
    content = template.render(context, self._request)
  File "/usr/local/lib/python2.7/dist-packages/django/template/backends/django.py", line 74, in render
    return self.template.render(context)
  File "/usr/local/lib/python2.7/dist-packages/django/template/base.py", line 209, in render
    return self._render(context)
  File "/usr/local/lib/python2.7/dist-packages/django/template/base.py", line 201, in _render
    return self.nodelist.render(context)
  File "/usr/local/lib/python2.7/dist-packages/django/template/base.py", line 903, in render
    bit = self.render_node(node, context)
  File "/usr/local/lib/python2.7/dist-packages/django/template/debug.py", line 79, in render_node
    return node.render(context)
  File "/usr/local/lib/python2.7/dist-packages/django/template/defaulttags.py", line 507, in render
    six.reraise(*exc_info)
  File "/usr/local/lib/python2.7/dist-packages/django/template/defaulttags.py", line 493, in render
    url = reverse(view_name, args=args, kwargs=kwargs, current_app=current_app)
  File "/usr/local/lib/python2.7/dist-packages/django/core/urlresolvers.py", line 579, in reverse
    return force_text(iri_to_uri(resolver._reverse_with_prefix(view, prefix, *args, **kwargs)))
  File "/usr/local/lib/python2.7/dist-packages/django/core/urlresolvers.py", line 496, in _reverse_with_prefix
    (lookup_view_s, args, kwargs, len(patterns), patterns))
NoReverseMatch: Reverse for 'addChoice' with arguments '(2L,)' and keyword arguments '{}' not found. 0 pattern(s) tried: []
2015-07-13 17:50:02,047 [ERROR] django.request: Internal Server Error: /polls/2/
Traceback (most recent call last):
  File "/usr/local/lib/python2.7/dist-packages/django/core/handlers/base.py", line 164, in get_response
    response = response.render()
  File "/usr/local/lib/python2.7/dist-packages/django/template/response.py", line 158, in render
    self.content = self.rendered_content
  File "/usr/local/lib/python2.7/dist-packages/django/template/response.py", line 135, in rendered_content
    content = template.render(context, self._request)
  File "/usr/local/lib/python2.7/dist-packages/django/template/backends/django.py", line 74, in render
    return self.template.render(context)
  File "/usr/local/lib/python2.7/dist-packages/django/template/base.py", line 209, in render
    return self._render(context)
  File "/usr/local/lib/python2.7/dist-packages/django/template/base.py", line 201, in _render
    return self.nodelist.render(context)
  File "/usr/local/lib/python2.7/dist-packages/django/template/base.py", line 903, in render
    bit = self.render_node(node, context)
  File "/usr/local/lib/python2.7/dist-packages/django/template/debug.py", line 79, in render_node
    return node.render(context)
  File "/usr/local/lib/python2.7/dist-packages/django/template/defaulttags.py", line 507, in render
    six.reraise(*exc_info)
  File "/usr/local/lib/python2.7/dist-packages/django/template/defaulttags.py", line 493, in render
    url = reverse(view_name, args=args, kwargs=kwargs, current_app=current_app)
  File "/usr/local/lib/python2.7/dist-packages/django/core/urlresolvers.py", line 579, in reverse
    return force_text(iri_to_uri(resolver._reverse_with_prefix(view, prefix, *args, **kwargs)))
  File "/usr/local/lib/python2.7/dist-packages/django/core/urlresolvers.py", line 496, in _reverse_with_prefix
    (lookup_view_s, args, kwargs, len(patterns), patterns))
NoReverseMatch: Reverse for 'addChoice' with arguments '(2L,)' and keyword arguments '{}' not found. 0 pattern(s) tried: []
2015-07-13 17:52:54,539 [ERROR] django.request: Internal Server Error: /polls/2/
Traceback (most recent call last):
  File "/usr/local/lib/python2.7/dist-packages/django/core/handlers/base.py", line 164, in get_response
    response = response.render()
  File "/usr/local/lib/python2.7/dist-packages/django/template/response.py", line 158, in render
    self.content = self.rendered_content
  File "/usr/local/lib/python2.7/dist-packages/django/template/response.py", line 135, in rendered_content
    content = template.render(context, self._request)
  File "/usr/local/lib/python2.7/dist-packages/django/template/backends/django.py", line 74, in render
    return self.template.render(context)
  File "/usr/local/lib/python2.7/dist-packages/django/template/base.py", line 209, in render
    return self._render(context)
  File "/usr/local/lib/python2.7/dist-packages/django/template/base.py", line 201, in _render
    return self.nodelist.render(context)
  File "/usr/local/lib/python2.7/dist-packages/django/template/base.py", line 903, in render
    bit = self.render_node(node, context)
  File "/usr/local/lib/python2.7/dist-packages/django/template/debug.py", line 79, in render_node
    return node.render(context)
  File "/usr/local/lib/python2.7/dist-packages/django/template/defaulttags.py", line 507, in render
    six.reraise(*exc_info)
  File "/usr/local/lib/python2.7/dist-packages/django/template/defaulttags.py", line 493, in render
    url = reverse(view_name, args=args, kwargs=kwargs, current_app=current_app)
  File "/usr/local/lib/python2.7/dist-packages/django/core/urlresolvers.py", line 579, in reverse
    return force_text(iri_to_uri(resolver._reverse_with_prefix(view, prefix, *args, **kwargs)))
  File "/usr/local/lib/python2.7/dist-packages/django/core/urlresolvers.py", line 496, in _reverse_with_prefix
    (lookup_view_s, args, kwargs, len(patterns), patterns))
NoReverseMatch: Reverse for 'addChoice' with arguments '(2L,)' and keyword arguments '{}' not found. 0 pattern(s) tried: []
2015-07-13 20:48:16,362 [WARNING] django.request: Not Found: /favicon.ico
2015-07-13 20:48:26,100 [ERROR] django.request: Internal Server Error: /polls/2/addChoice/
Traceback (most recent call last):
  File "/usr/local/lib/python2.7/dist-packages/django/core/handlers/base.py", line 132, in get_response
    response = wrapped_callback(request, *callback_args, **callback_kwargs)
  File "/home/george/djangoSite/polls/views.py", line 66, in newChoice
    logger.error(request.POST['newChoice'])
  File "/usr/local/lib/python2.7/dist-packages/django/utils/datastructures.py", line 322, in __getitem__
    raise MultiValueDictKeyError(repr(key))
MultiValueDictKeyError: "'newChoice'"
2015-07-13 20:50:41,519 [ERROR] django.request: Internal Server Error: /polls/2/addChoice/
Traceback (most recent call last):
  File "/usr/local/lib/python2.7/dist-packages/django/core/handlers/base.py", line 132, in get_response
    response = wrapped_callback(request, *callback_args, **callback_kwargs)
  File "/home/george/djangoSite/polls/views.py", line 66, in newChoice
    logger.error(request.POST['newChoice'])
  File "/usr/local/lib/python2.7/dist-packages/django/utils/datastructures.py", line 322, in __getitem__
    raise MultiValueDictKeyError(repr(key))
MultiValueDictKeyError: "'newChoice'"
2015-07-13 20:50:47,170 [WARNING] django.request: Forbidden (CSRF token missing or incorrect.): /polls/2/addChoice/
2015-07-13 20:51:35,114 [ERROR] django.request: Internal Server Error: /polls/2/addChoice/
Traceback (most recent call last):
  File "/usr/local/lib/python2.7/dist-packages/django/core/handlers/base.py", line 151, in get_response
    % (callback.__module__, view_name))
ValueError: The view polls.views.newChoice didn't return an HttpResponse object. It returned None instead.
2015-07-13 20:52:36,827 [ERROR] django.request: Internal Server Error: /polls/2/addChoice/
Traceback (most recent call last):
  File "/usr/local/lib/python2.7/dist-packages/django/core/handlers/base.py", line 132, in get_response
    response = wrapped_callback(request, *callback_args, **callback_kwargs)
  File "/home/george/djangoSite/polls/views.py", line 67, in newChoice
    return HttpResponse(reverse('polls:details'))
  File "/usr/local/lib/python2.7/dist-packages/django/core/urlresolvers.py", line 579, in reverse
    return force_text(iri_to_uri(resolver._reverse_with_prefix(view, prefix, *args, **kwargs)))
  File "/usr/local/lib/python2.7/dist-packages/django/core/urlresolvers.py", line 496, in _reverse_with_prefix
    (lookup_view_s, args, kwargs, len(patterns), patterns))
NoReverseMatch: Reverse for 'details' with arguments '()' and keyword arguments '{}' not found. 0 pattern(s) tried: []
2015-07-13 20:53:46,109 [ERROR] django.request: Internal Server Error: /polls/2/addChoice/
Traceback (most recent call last):
  File "/usr/local/lib/python2.7/dist-packages/django/core/handlers/base.py", line 132, in get_response
    response = wrapped_callback(request, *callback_args, **callback_kwargs)
  File "/home/george/djangoSite/polls/views.py", line 67, in newChoice
    return HttpResponse(reverse('polls:details', args=(question.id)))
  File "/usr/local/lib/python2.7/dist-packages/django/core/urlresolvers.py", line 579, in reverse
    return force_text(iri_to_uri(resolver._reverse_with_prefix(view, prefix, *args, **kwargs)))
TypeError: _reverse_with_prefix() argument after * must be a sequence, not long
2015-07-13 20:54:18,385 [ERROR] django.request: Internal Server Error: /polls/2/addChoice/
Traceback (most recent call last):
  File "/usr/local/lib/python2.7/dist-packages/django/core/handlers/base.py", line 132, in get_response
    response = wrapped_callback(request, *callback_args, **callback_kwargs)
  File "/home/george/djangoSite/polls/views.py", line 67, in newChoice
    return HttpResponse(reverse('polls:details', args=(question.id,)))
  File "/usr/local/lib/python2.7/dist-packages/django/core/urlresolvers.py", line 579, in reverse
    return force_text(iri_to_uri(resolver._reverse_with_prefix(view, prefix, *args, **kwargs)))
  File "/usr/local/lib/python2.7/dist-packages/django/core/urlresolvers.py", line 496, in _reverse_with_prefix
    (lookup_view_s, args, kwargs, len(patterns), patterns))
NoReverseMatch: Reverse for 'details' with arguments '(2L,)' and keyword arguments '{}' not found. 0 pattern(s) tried: []
2015-07-13 20:56:34,578 [ERROR] django.request: Internal Server Error: /polls/2/addChoice/
Traceback (most recent call last):
  File "/usr/local/lib/python2.7/dist-packages/django/core/handlers/base.py", line 132, in get_response
    response = wrapped_callback(request, *callback_args, **callback_kwargs)
  File "/home/george/djangoSite/polls/views.py", line 67, in newChoice
    return HttpResponseRedirect(reverse('polls:details', args=(question.id,)))
  File "/usr/local/lib/python2.7/dist-packages/django/core/urlresolvers.py", line 579, in reverse
    return force_text(iri_to_uri(resolver._reverse_with_prefix(view, prefix, *args, **kwargs)))
  File "/usr/local/lib/python2.7/dist-packages/django/core/urlresolvers.py", line 496, in _reverse_with_prefix
    (lookup_view_s, args, kwargs, len(patterns), patterns))
NoReverseMatch: Reverse for 'details' with arguments '(2L,)' and keyword arguments '{}' not found. 0 pattern(s) tried: []
2015-07-14 04:49:19,684 [WARNING] django.request: Not Found: /Ringing.at.your.dorbell!
2015-07-14 04:49:22,734 [WARNING] django.request: Not Found: /Diagnostics.asp
2015-07-14 05:26:42,237 [WARNING] django.request: Not Found: /favicon.ico
2015-07-14 11:48:52,009 [WARNING] django.request: Not Found: /Ringing.at.your.dorbell!
2015-07-14 11:48:59,620 [WARNING] django.request: Not Found: /Diagnostics.asp
2015-07-14 14:04:11,566 [WARNING] django.request: Not Found: /testproxy.php
2015-07-14 18:14:40,058 [WARNING] django.request: Not Found: /etc/lib/pChart2/examples/index.php
2015-07-14 20:20:03,000 [WARNING] django.request: Not Found: /favicon.ico
2015-07-14 20:57:41,876 [WARNING] django.request: Not Found: /favicon.ico
2015-07-14 20:58:17,658 [ERROR] django.request: Internal Server Error: /polls/2/addChoice/
Traceback (most recent call last):
  File "/usr/local/lib/python2.7/dist-packages/django/core/handlers/base.py", line 132, in get_response
    response = wrapped_callback(request, *callback_args, **callback_kwargs)
  File "/home/george/djangoSite/polls/views.py", line 67, in newChoice
    return HttpResponseRedirect(reverse('polls:details', args=(question.id,)))
  File "/usr/local/lib/python2.7/dist-packages/django/core/urlresolvers.py", line 579, in reverse
    return force_text(iri_to_uri(resolver._reverse_with_prefix(view, prefix, *args, **kwargs)))
  File "/usr/local/lib/python2.7/dist-packages/django/core/urlresolvers.py", line 496, in _reverse_with_prefix
    (lookup_view_s, args, kwargs, len(patterns), patterns))
NoReverseMatch: Reverse for 'details' with arguments '(2L,)' and keyword arguments '{}' not found. 0 pattern(s) tried: []
2015-07-14 21:03:13,290 [WARNING] django.request: Not Found: /fhiuewhkjdsn
2015-07-14 21:03:13,320 [WARNING] django.request: Not Found: /fhiuewhkjdsn
2015-07-14 21:04:49,298 [ERROR] django.request: Internal Server Error: /polls/2/addChoice/
Traceback (most recent call last):
  File "/usr/local/lib/python2.7/dist-packages/django/core/handlers/base.py", line 132, in get_response
    response = wrapped_callback(request, *callback_args, **callback_kwargs)
  File "/home/george/djangoSite/polls/views.py", line 67, in newChoice
    return HttpResponseRedirect(reverse('polls:details', kwargs=({'pk':question.pk})))
  File "/usr/local/lib/python2.7/dist-packages/django/core/urlresolvers.py", line 579, in reverse
    return force_text(iri_to_uri(resolver._reverse_with_prefix(view, prefix, *args, **kwargs)))
  File "/usr/local/lib/python2.7/dist-packages/django/core/urlresolvers.py", line 496, in _reverse_with_prefix
    (lookup_view_s, args, kwargs, len(patterns), patterns))
NoReverseMatch: Reverse for 'details' with arguments '()' and keyword arguments '{'pk': 2L}' not found. 0 pattern(s) tried: []
2015-07-14 21:08:39,645 [ERROR] django.request: Internal Server Error: /polls/2/addChoice/
Traceback (most recent call last):
  File "/usr/local/lib/python2.7/dist-packages/django/core/handlers/base.py", line 132, in get_response
    response = wrapped_callback(request, *callback_args, **callback_kwargs)
  File "/home/george/djangoSite/polls/views.py", line 66, in newChoice
    question.choice_set.add(Choice(request.POST['newChoice']))
  File "/usr/local/lib/python2.7/dist-packages/django/db/models/fields/related.py", line 744, in add
    obj.save()
  File "/usr/local/lib/python2.7/dist-packages/django/db/models/base.py", line 710, in save
    force_update=force_update, update_fields=update_fields)
  File "/usr/local/lib/python2.7/dist-packages/django/db/models/base.py", line 738, in save_base
    updated = self._save_table(raw, cls, force_insert, force_update, using, update_fields)
  File "/usr/local/lib/python2.7/dist-packages/django/db/models/base.py", line 803, in _save_table
    forced_update)
  File "/usr/local/lib/python2.7/dist-packages/django/db/models/base.py", line 833, in _do_update
    filtered = base_qs.filter(pk=pk_val)
  File "/usr/local/lib/python2.7/dist-packages/django/db/models/query.py", line 679, in filter
    return self._filter_or_exclude(False, *args, **kwargs)
  File "/usr/local/lib/python2.7/dist-packages/django/db/models/query.py", line 697, in _filter_or_exclude
    clone.query.add_q(Q(*args, **kwargs))
  File "/usr/local/lib/python2.7/dist-packages/django/db/models/sql/query.py", line 1304, in add_q
    clause, require_inner = self._add_q(where_part, self.used_aliases)
  File "/usr/local/lib/python2.7/dist-packages/django/db/models/sql/query.py", line 1332, in _add_q
    allow_joins=allow_joins, split_subq=split_subq,
  File "/usr/local/lib/python2.7/dist-packages/django/db/models/sql/query.py", line 1203, in build_filter
    condition = self.build_lookup(lookups, col, value)
  File "/usr/local/lib/python2.7/dist-packages/django/db/models/sql/query.py", line 1096, in build_lookup
    return final_lookup(lhs, rhs)
  File "/usr/local/lib/python2.7/dist-packages/django/db/models/lookups.py", line 96, in __init__
    self.rhs = self.get_prep_lookup()
  File "/usr/local/lib/python2.7/dist-packages/django/db/models/lookups.py", line 134, in get_prep_lookup
    return self.lhs.output_field.get_prep_lookup(self.lookup_name, self.rhs)
  File "/usr/local/lib/python2.7/dist-packages/django/db/models/fields/__init__.py", line 727, in get_prep_lookup
    return self.get_prep_value(value)
  File "/usr/local/lib/python2.7/dist-packages/django/db/models/fields/__init__.py", line 985, in get_prep_value
    return int(value)
ValueError: invalid literal for int() with base 10: 'Money'
2015-07-14 21:25:40,816 [WARNING] django.request: Not Found: /favicon.ico
2015-07-14 21:58:38,047 [WARNING] django.request: Not Found: /favicon.ico
2015-07-14 23:21:55,483 [WARNING] django.request: Not Found: /favicon.ico
2015-07-14 23:34:08,040 [WARNING] django.request: Not Found: /favicon.ico
2015-07-15 00:10:44,248 [WARNING] django.request: Not Found: /favicon.ico
2015-07-15 12:59:14,054 [WARNING] django.request: Not Found: /favicon.ico
2015-07-15 12:59:14,091 [WARNING] django.request: Not Found: /favicon.ico
2015-07-15 15:06:07,783 [WARNING] django.request: Not Found: /favicon.ico
2015-07-15 17:51:05,913 [WARNING] django.request: Not Found: /static/bootstrap/normalize.css
2015-07-15 17:51:05,923 [WARNING] django.request: Not Found: /static/bootstrap/bootstrap.css
2015-07-15 17:51:08,735 [WARNING] django.request: Not Found: /static/bootstrap/normalize.css
2015-07-15 17:51:08,735 [WARNING] django.request: Not Found: /static/bootstrap/bootstrap.css
2015-07-15 17:52:35,568 [WARNING] django.request: Not Found: /static/bootstrap/normalize.css
2015-07-15 17:52:35,580 [WARNING] django.request: Not Found: /static/bootstrap/bootstrap.css
2015-07-15 17:54:09,561 [WARNING] django.request: Not Found: /static/bootstrap/bootstrap.css
2015-07-15 17:54:09,561 [WARNING] django.request: Not Found: /static/bootstrap/normalize.css
2015-07-15 17:54:51,999 [WARNING] django.request: Not Found: /static/bootstrap/normalize.css
2015-07-15 17:54:52,029 [WARNING] django.request: Not Found: /static/bootstrap/bootstrap.css
2015-07-15 17:56:02,674 [WARNING] django.request: Not Found: /static/bootstrap/normalize.css
2015-07-15 17:56:02,690 [WARNING] django.request: Not Found: /static/bootstrap/bootstrap.css
2015-07-15 17:57:36,630 [WARNING] django.request: Not Found: /static/bootstrap/normalize.css
2015-07-15 17:57:36,645 [WARNING] django.request: Not Found: /static/bootstrap/bootstrap.css
2015-07-15 17:58:13,511 [WARNING] django.request: Not Found: /static/bootstrap/normalize.css
2015-07-15 17:58:13,523 [WARNING] django.request: Not Found: /static/bootstrap/bootstrap.css
2015-07-15 17:58:39,187 [WARNING] django.request: Not Found: /static/bootstrap/normalize.css
2015-07-15 17:58:39,198 [WARNING] django.request: Not Found: /static/bootstrap/bootstrap.css
2015-07-15 17:58:56,305 [WARNING] django.request: Not Found: /static/bootstrap/normalize.css
2015-07-15 17:58:56,319 [WARNING] django.request: Not Found: /static/bootstrap/bootstrap.css
2015-07-15 18:00:31,087 [WARNING] django.request: Not Found: /static/bootstrap/normalize.css
2015-07-15 18:00:31,098 [WARNING] django.request: Not Found: /static/bootstrap/bootstrap.css
2015-07-15 18:06:27,135 [WARNING] django.request: Not Found: /static/bootstrap/normalize.css
2015-07-15 18:06:27,153 [WARNING] django.request: Not Found: /static/bootstrap/bootstrap.css
2015-07-15 18:06:28,411 [WARNING] django.request: Not Found: /static/bootstrap/normalize.css
2015-07-15 18:06:28,419 [WARNING] django.request: Not Found: /static/bootstrap/bootstrap.css
2015-07-15 18:06:29,746 [WARNING] django.request: Not Found: /static/bootstrap/normalize.css
2015-07-15 18:06:29,757 [WARNING] django.request: Not Found: /static/bootstrap/bootstrap.css
2015-07-15 18:08:15,635 [WARNING] django.request: Not Found: /static/bootstrap/normalize.css
2015-07-15 18:08:15,653 [WARNING] django.request: Not Found: /static/bootstrap/bootstrap.css
2015-07-15 18:08:16,615 [WARNING] django.request: Not Found: /static/bootstrap/normalize.css
2015-07-15 18:08:16,623 [WARNING] django.request: Not Found: /static/bootstrap/bootstrap.css
2015-07-15 18:09:44,365 [ERROR] django.request: Internal Server Error: /static/bootstrap/normalize.css
Traceback (most recent call last):
  File "/usr/local/lib/python2.7/dist-packages/django/core/handlers/base.py", line 132, in get_response
    response = wrapped_callback(request, *callback_args, **callback_kwargs)
  File "/usr/local/lib/python2.7/dist-packages/django/contrib/staticfiles/views.py", line 34, in serve
    absolute_path = finders.find(normalized_path)
  File "/usr/local/lib/python2.7/dist-packages/django/contrib/staticfiles/finders.py", line 249, in find
    for finder in get_finders():
  File "/usr/local/lib/python2.7/dist-packages/django/contrib/staticfiles/finders.py", line 264, in get_finders
    yield get_finder(finder_path)
  File "/usr/local/lib/python2.7/dist-packages/django/utils/lru_cache.py", line 101, in wrapper
    result = user_function(*args, **kwds)
  File "/usr/local/lib/python2.7/dist-packages/django/contrib/staticfiles/finders.py", line 277, in get_finder
    return Finder()
  File "/usr/local/lib/python2.7/dist-packages/django/contrib/staticfiles/finders.py", line 66, in __init__
    "The STATICFILES_DIRS setting should "
ImproperlyConfigured: The STATICFILES_DIRS setting should not contain the STATIC_ROOT setting
2015-07-15 18:09:44,387 [ERROR] django.request: Internal Server Error: /static/bootstrap/bootstrap.css
Traceback (most recent call last):
  File "/usr/local/lib/python2.7/dist-packages/django/core/handlers/base.py", line 132, in get_response
    response = wrapped_callback(request, *callback_args, **callback_kwargs)
  File "/usr/local/lib/python2.7/dist-packages/django/contrib/staticfiles/views.py", line 34, in serve
    absolute_path = finders.find(normalized_path)
  File "/usr/local/lib/python2.7/dist-packages/django/contrib/staticfiles/finders.py", line 249, in find
    for finder in get_finders():
  File "/usr/local/lib/python2.7/dist-packages/django/contrib/staticfiles/finders.py", line 264, in get_finders
    yield get_finder(finder_path)
  File "/usr/local/lib/python2.7/dist-packages/django/utils/lru_cache.py", line 101, in wrapper
    result = user_function(*args, **kwds)
  File "/usr/local/lib/python2.7/dist-packages/django/contrib/staticfiles/finders.py", line 277, in get_finder
    return Finder()
  File "/usr/local/lib/python2.7/dist-packages/django/contrib/staticfiles/finders.py", line 66, in __init__
    "The STATICFILES_DIRS setting should "
ImproperlyConfigured: The STATICFILES_DIRS setting should not contain the STATIC_ROOT setting
2015-07-15 18:09:44,414 [ERROR] django.request: Internal Server Error: /static/polls/style.css
Traceback (most recent call last):
  File "/usr/local/lib/python2.7/dist-packages/django/core/handlers/base.py", line 132, in get_response
    response = wrapped_callback(request, *callback_args, **callback_kwargs)
  File "/usr/local/lib/python2.7/dist-packages/django/contrib/staticfiles/views.py", line 34, in serve
    absolute_path = finders.find(normalized_path)
  File "/usr/local/lib/python2.7/dist-packages/django/contrib/staticfiles/finders.py", line 249, in find
    for finder in get_finders():
  File "/usr/local/lib/python2.7/dist-packages/django/contrib/staticfiles/finders.py", line 264, in get_finders
    yield get_finder(finder_path)
  File "/usr/local/lib/python2.7/dist-packages/django/utils/lru_cache.py", line 101, in wrapper
    result = user_function(*args, **kwds)
  File "/usr/local/lib/python2.7/dist-packages/django/contrib/staticfiles/finders.py", line 277, in get_finder
    return Finder()
  File "/usr/local/lib/python2.7/dist-packages/django/contrib/staticfiles/finders.py", line 66, in __init__
    "The STATICFILES_DIRS setting should "
ImproperlyConfigured: The STATICFILES_DIRS setting should not contain the STATIC_ROOT setting
2015-07-15 18:09:47,694 [ERROR] django.request: Internal Server Error: /static/bootstrap/normalize.css
Traceback (most recent call last):
  File "/usr/local/lib/python2.7/dist-packages/django/core/handlers/base.py", line 132, in get_response
    response = wrapped_callback(request, *callback_args, **callback_kwargs)
  File "/usr/local/lib/python2.7/dist-packages/django/contrib/staticfiles/views.py", line 34, in serve
    absolute_path = finders.find(normalized_path)
  File "/usr/local/lib/python2.7/dist-packages/django/contrib/staticfiles/finders.py", line 249, in find
    for finder in get_finders():
  File "/usr/local/lib/python2.7/dist-packages/django/contrib/staticfiles/finders.py", line 264, in get_finders
    yield get_finder(finder_path)
  File "/usr/local/lib/python2.7/dist-packages/django/utils/lru_cache.py", line 101, in wrapper
    result = user_function(*args, **kwds)
  File "/usr/local/lib/python2.7/dist-packages/django/contrib/staticfiles/finders.py", line 277, in get_finder
    return Finder()
  File "/usr/local/lib/python2.7/dist-packages/django/contrib/staticfiles/finders.py", line 66, in __init__
    "The STATICFILES_DIRS setting should "
ImproperlyConfigured: The STATICFILES_DIRS setting should not contain the STATIC_ROOT setting
2015-07-15 18:09:47,711 [ERROR] django.request: Internal Server Error: /static/bootstrap/bootstrap.css
Traceback (most recent call last):
  File "/usr/local/lib/python2.7/dist-packages/django/core/handlers/base.py", line 132, in get_response
    response = wrapped_callback(request, *callback_args, **callback_kwargs)
  File "/usr/local/lib/python2.7/dist-packages/django/contrib/staticfiles/views.py", line 34, in serve
    absolute_path = finders.find(normalized_path)
  File "/usr/local/lib/python2.7/dist-packages/django/contrib/staticfiles/finders.py", line 249, in find
    for finder in get_finders():
  File "/usr/local/lib/python2.7/dist-packages/django/contrib/staticfiles/finders.py", line 264, in get_finders
    yield get_finder(finder_path)
  File "/usr/local/lib/python2.7/dist-packages/django/utils/lru_cache.py", line 101, in wrapper
    result = user_function(*args, **kwds)
  File "/usr/local/lib/python2.7/dist-packages/django/contrib/staticfiles/finders.py", line 277, in get_finder
    return Finder()
  File "/usr/local/lib/python2.7/dist-packages/django/contrib/staticfiles/finders.py", line 66, in __init__
    "The STATICFILES_DIRS setting should "
ImproperlyConfigured: The STATICFILES_DIRS setting should not contain the STATIC_ROOT setting
2015-07-15 18:09:47,728 [ERROR] django.request: Internal Server Error: /static/polls/style.css
Traceback (most recent call last):
  File "/usr/local/lib/python2.7/dist-packages/django/core/handlers/base.py", line 132, in get_response
    response = wrapped_callback(request, *callback_args, **callback_kwargs)
  File "/usr/local/lib/python2.7/dist-packages/django/contrib/staticfiles/views.py", line 34, in serve
    absolute_path = finders.find(normalized_path)
  File "/usr/local/lib/python2.7/dist-packages/django/contrib/staticfiles/finders.py", line 249, in find
    for finder in get_finders():
  File "/usr/local/lib/python2.7/dist-packages/django/contrib/staticfiles/finders.py", line 264, in get_finders
    yield get_finder(finder_path)
  File "/usr/local/lib/python2.7/dist-packages/django/utils/lru_cache.py", line 101, in wrapper
    result = user_function(*args, **kwds)
  File "/usr/local/lib/python2.7/dist-packages/django/contrib/staticfiles/finders.py", line 277, in get_finder
    return Finder()
  File "/usr/local/lib/python2.7/dist-packages/django/contrib/staticfiles/finders.py", line 66, in __init__
    "The STATICFILES_DIRS setting should "
ImproperlyConfigured: The STATICFILES_DIRS setting should not contain the STATIC_ROOT setting
2015-07-15 18:10:41,704 [ERROR] django.request: Internal Server Error: /static/bootstrap/normalize.css
Traceback (most recent call last):
  File "/usr/local/lib/python2.7/dist-packages/django/core/handlers/base.py", line 132, in get_response
    response = wrapped_callback(request, *callback_args, **callback_kwargs)
  File "/usr/local/lib/python2.7/dist-packages/django/contrib/staticfiles/views.py", line 34, in serve
    absolute_path = finders.find(normalized_path)
  File "/usr/local/lib/python2.7/dist-packages/django/contrib/staticfiles/finders.py", line 249, in find
    for finder in get_finders():
  File "/usr/local/lib/python2.7/dist-packages/django/contrib/staticfiles/finders.py", line 264, in get_finders
    yield get_finder(finder_path)
  File "/usr/local/lib/python2.7/dist-packages/django/utils/lru_cache.py", line 101, in wrapper
    result = user_function(*args, **kwds)
  File "/usr/local/lib/python2.7/dist-packages/django/contrib/staticfiles/finders.py", line 277, in get_finder
    return Finder()
  File "/usr/local/lib/python2.7/dist-packages/django/contrib/staticfiles/finders.py", line 66, in __init__
    "The STATICFILES_DIRS setting should "
ImproperlyConfigured: The STATICFILES_DIRS setting should not contain the STATIC_ROOT setting
2015-07-15 18:10:41,724 [ERROR] django.request: Internal Server Error: /static/bootstrap/bootstrap.css
Traceback (most recent call last):
  File "/usr/local/lib/python2.7/dist-packages/django/core/handlers/base.py", line 132, in get_response
    response = wrapped_callback(request, *callback_args, **callback_kwargs)
  File "/usr/local/lib/python2.7/dist-packages/django/contrib/staticfiles/views.py", line 34, in serve
    absolute_path = finders.find(normalized_path)
  File "/usr/local/lib/python2.7/dist-packages/django/contrib/staticfiles/finders.py", line 249, in find
    for finder in get_finders():
  File "/usr/local/lib/python2.7/dist-packages/django/contrib/staticfiles/finders.py", line 264, in get_finders
    yield get_finder(finder_path)
  File "/usr/local/lib/python2.7/dist-packages/django/utils/lru_cache.py", line 101, in wrapper
    result = user_function(*args, **kwds)
  File "/usr/local/lib/python2.7/dist-packages/django/contrib/staticfiles/finders.py", line 277, in get_finder
    return Finder()
  File "/usr/local/lib/python2.7/dist-packages/django/contrib/staticfiles/finders.py", line 66, in __init__
    "The STATICFILES_DIRS setting should "
ImproperlyConfigured: The STATICFILES_DIRS setting should not contain the STATIC_ROOT setting
2015-07-15 18:10:41,732 [ERROR] django.request: Internal Server Error: /static/polls/style.css
Traceback (most recent call last):
  File "/usr/local/lib/python2.7/dist-packages/django/core/handlers/base.py", line 132, in get_response
    response = wrapped_callback(request, *callback_args, **callback_kwargs)
  File "/usr/local/lib/python2.7/dist-packages/django/contrib/staticfiles/views.py", line 34, in serve
    absolute_path = finders.find(normalized_path)
  File "/usr/local/lib/python2.7/dist-packages/django/contrib/staticfiles/finders.py", line 249, in find
    for finder in get_finders():
  File "/usr/local/lib/python2.7/dist-packages/django/contrib/staticfiles/finders.py", line 264, in get_finders
    yield get_finder(finder_path)
  File "/usr/local/lib/python2.7/dist-packages/django/utils/lru_cache.py", line 101, in wrapper
    result = user_function(*args, **kwds)
  File "/usr/local/lib/python2.7/dist-packages/django/contrib/staticfiles/finders.py", line 277, in get_finder
    return Finder()
  File "/usr/local/lib/python2.7/dist-packages/django/contrib/staticfiles/finders.py", line 66, in __init__
    "The STATICFILES_DIRS setting should "
ImproperlyConfigured: The STATICFILES_DIRS setting should not contain the STATIC_ROOT setting
2015-07-15 18:10:42,940 [ERROR] django.request: Internal Server Error: /static/bootstrap/normalize.css
Traceback (most recent call last):
  File "/usr/local/lib/python2.7/dist-packages/django/core/handlers/base.py", line 132, in get_response
    response = wrapped_callback(request, *callback_args, **callback_kwargs)
  File "/usr/local/lib/python2.7/dist-packages/django/contrib/staticfiles/views.py", line 34, in serve
    absolute_path = finders.find(normalized_path)
  File "/usr/local/lib/python2.7/dist-packages/django/contrib/staticfiles/finders.py", line 249, in find
    for finder in get_finders():
  File "/usr/local/lib/python2.7/dist-packages/django/contrib/staticfiles/finders.py", line 264, in get_finders
    yield get_finder(finder_path)
  File "/usr/local/lib/python2.7/dist-packages/django/utils/lru_cache.py", line 101, in wrapper
    result = user_function(*args, **kwds)
  File "/usr/local/lib/python2.7/dist-packages/django/contrib/staticfiles/finders.py", line 277, in get_finder
    return Finder()
  File "/usr/local/lib/python2.7/dist-packages/django/contrib/staticfiles/finders.py", line 66, in __init__
    "The STATICFILES_DIRS setting should "
ImproperlyConfigured: The STATICFILES_DIRS setting should not contain the STATIC_ROOT setting
2015-07-15 18:10:42,965 [ERROR] django.request: Internal Server Error: /static/bootstrap/bootstrap.css
Traceback (most recent call last):
  File "/usr/local/lib/python2.7/dist-packages/django/core/handlers/base.py", line 132, in get_response
    response = wrapped_callback(request, *callback_args, **callback_kwargs)
  File "/usr/local/lib/python2.7/dist-packages/django/contrib/staticfiles/views.py", line 34, in serve
    absolute_path = finders.find(normalized_path)
  File "/usr/local/lib/python2.7/dist-packages/django/contrib/staticfiles/finders.py", line 249, in find
    for finder in get_finders():
  File "/usr/local/lib/python2.7/dist-packages/django/contrib/staticfiles/finders.py", line 264, in get_finders
    yield get_finder(finder_path)
  File "/usr/local/lib/python2.7/dist-packages/django/utils/lru_cache.py", line 101, in wrapper
    result = user_function(*args, **kwds)
  File "/usr/local/lib/python2.7/dist-packages/django/contrib/staticfiles/finders.py", line 277, in get_finder
    return Finder()
  File "/usr/local/lib/python2.7/dist-packages/django/contrib/staticfiles/finders.py", line 66, in __init__
    "The STATICFILES_DIRS setting should "
ImproperlyConfigured: The STATICFILES_DIRS setting should not contain the STATIC_ROOT setting
2015-07-15 18:10:42,966 [ERROR] django.request: Internal Server Error: /static/polls/style.css
Traceback (most recent call last):
  File "/usr/local/lib/python2.7/dist-packages/django/core/handlers/base.py", line 132, in get_response
    response = wrapped_callback(request, *callback_args, **callback_kwargs)
  File "/usr/local/lib/python2.7/dist-packages/django/contrib/staticfiles/views.py", line 34, in serve
    absolute_path = finders.find(normalized_path)
  File "/usr/local/lib/python2.7/dist-packages/django/contrib/staticfiles/finders.py", line 249, in find
    for finder in get_finders():
  File "/usr/local/lib/python2.7/dist-packages/django/contrib/staticfiles/finders.py", line 264, in get_finders
    yield get_finder(finder_path)
  File "/usr/local/lib/python2.7/dist-packages/django/utils/lru_cache.py", line 101, in wrapper
    result = user_function(*args, **kwds)
  File "/usr/local/lib/python2.7/dist-packages/django/contrib/staticfiles/finders.py", line 277, in get_finder
    return Finder()
  File "/usr/local/lib/python2.7/dist-packages/django/contrib/staticfiles/finders.py", line 66, in __init__
    "The STATICFILES_DIRS setting should "
ImproperlyConfigured: The STATICFILES_DIRS setting should not contain the STATIC_ROOT setting
2015-07-15 18:11:08,409 [WARNING] django.request: Not Found: /static/bootstrap/normalize.css
2015-07-15 18:11:08,424 [WARNING] django.request: Not Found: /static/bootstrap/bootstrap.css
2015-07-15 18:20:39,214 [WARNING] django.request: Not Found: /static/bootstrap/normalize.css
2015-07-15 18:20:39,232 [WARNING] django.request: Not Found: /static/bootstrap/bootstrap.css
2015-07-15 18:38:27,143 [WARNING] django.request: Not Found: /static/bootstrap/normalize.css
2015-07-15 18:38:27,161 [WARNING] django.request: Not Found: /static/bootstrap/bootstrap.css
2015-07-15 18:38:28,239 [WARNING] django.request: Not Found: /static/bootstrap/bootstrap.css
2015-07-15 18:38:28,240 [WARNING] django.request: Not Found: /static/bootstrap/normalize.css
2015-07-15 18:38:42,366 [WARNING] django.request: Not Found: /static/bootstrap/bootstrap.css.map
2015-07-15 18:38:52,899 [WARNING] django.request: Not Found: /static/bootstrap/bootstrap.css.map
2015-07-15 18:38:56,679 [WARNING] django.request: Not Found: /static/bootstrap/bootstrap.css.map
2015-07-15 18:38:57,446 [WARNING] django.request: Not Found: /static/bootstrap/bootstrap.css.map
2015-07-15 18:39:42,252 [WARNING] django.request: Not Found: /static/bootstrap/bootstrap.css.map
2015-07-15 18:39:42,959 [WARNING] django.request: Not Found: /static/bootstrap/bootstrap.css.map
2015-07-15 19:15:44,638 [ERROR] django.request: Internal Server Error: /polls/2/
Traceback (most recent call last):
  File "/usr/local/lib/python2.7/dist-packages/django/core/handlers/base.py", line 164, in get_response
    response = response.render()
  File "/usr/local/lib/python2.7/dist-packages/django/template/response.py", line 158, in render
    self.content = self.rendered_content
  File "/usr/local/lib/python2.7/dist-packages/django/template/response.py", line 133, in rendered_content
    template = self._resolve_template(self.template_name)
  File "/usr/local/lib/python2.7/dist-packages/django/template/response.py", line 88, in _resolve_template
    new_template = self.resolve_template(template)
  File "/usr/local/lib/python2.7/dist-packages/django/template/response.py", line 78, in resolve_template
    return loader.select_template(template, using=self.using)
  File "/usr/local/lib/python2.7/dist-packages/django/template/loader.py", line 64, in select_template
    return engine.get_template(template_name, dirs)
  File "/usr/local/lib/python2.7/dist-packages/django/template/backends/django.py", line 30, in get_template
    return Template(self.engine.get_template(template_name, dirs))
  File "/usr/local/lib/python2.7/dist-packages/django/template/engine.py", line 167, in get_template
    template, origin = self.find_template(template_name, dirs)
  File "/usr/local/lib/python2.7/dist-packages/django/template/engine.py", line 141, in find_template
    source, display_name = loader(name, dirs)
  File "/usr/local/lib/python2.7/dist-packages/django/template/loaders/base.py", line 13, in __call__
    return self.load_template(template_name, template_dirs)
  File "/usr/local/lib/python2.7/dist-packages/django/template/loaders/base.py", line 23, in load_template
    template = Template(source, origin, template_name, self.engine)
  File "/usr/local/lib/python2.7/dist-packages/django/template/base.py", line 190, in __init__
    self.nodelist = engine.compile_string(template_string, origin)
  File "/usr/local/lib/python2.7/dist-packages/django/template/engine.py", line 261, in compile_string
    return parser.parse()
  File "/usr/local/lib/python2.7/dist-packages/django/template/base.py", line 341, in parse
    compiled_result = compile_func(self, token)
  File "/usr/local/lib/python2.7/dist-packages/django/template/defaulttags.py", line 872, in do_for
    nodelist_loop = parser.parse(('empty', 'endfor',))
  File "/usr/local/lib/python2.7/dist-packages/django/template/base.py", line 341, in parse
    compiled_result = compile_func(self, token)
  File "/usr/local/lib/python2.7/dist-packages/django/template/defaulttags.py", line 871, in do_for
    sequence = parser.compile_filter(bits[in_index + 1])
  File "/usr/local/lib/python2.7/dist-packages/django/template/base.py", line 423, in compile_filter
    return FilterExpression(token, self)
  File "/usr/local/lib/python2.7/dist-packages/django/template/base.py", line 633, in __init__
    filter_func = parser.find_filter(filter_name)
  File "/usr/local/lib/python2.7/dist-packages/django/template/base.py", line 429, in find_filter
    raise TemplateSyntaxError("Invalid filter: '%s'" % filter_name)
TemplateSyntaxError: Invalid filter: 'get_range'
2015-07-15 19:17:15,355 [ERROR] django.request: Internal Server Error: /polls/2/
Traceback (most recent call last):
  File "/usr/local/lib/python2.7/dist-packages/django/core/handlers/base.py", line 164, in get_response
    response = response.render()
  File "/usr/local/lib/python2.7/dist-packages/django/template/response.py", line 158, in render
    self.content = self.rendered_content
  File "/usr/local/lib/python2.7/dist-packages/django/template/response.py", line 133, in rendered_content
    template = self._resolve_template(self.template_name)
  File "/usr/local/lib/python2.7/dist-packages/django/template/response.py", line 88, in _resolve_template
    new_template = self.resolve_template(template)
  File "/usr/local/lib/python2.7/dist-packages/django/template/response.py", line 78, in resolve_template
    return loader.select_template(template, using=self.using)
  File "/usr/local/lib/python2.7/dist-packages/django/template/loader.py", line 64, in select_template
    return engine.get_template(template_name, dirs)
  File "/usr/local/lib/python2.7/dist-packages/django/template/backends/django.py", line 30, in get_template
    return Template(self.engine.get_template(template_name, dirs))
  File "/usr/local/lib/python2.7/dist-packages/django/template/engine.py", line 167, in get_template
    template, origin = self.find_template(template_name, dirs)
  File "/usr/local/lib/python2.7/dist-packages/django/template/engine.py", line 141, in find_template
    source, display_name = loader(name, dirs)
  File "/usr/local/lib/python2.7/dist-packages/django/template/loaders/base.py", line 13, in __call__
    return self.load_template(template_name, template_dirs)
  File "/usr/local/lib/python2.7/dist-packages/django/template/loaders/base.py", line 23, in load_template
    template = Template(source, origin, template_name, self.engine)
  File "/usr/local/lib/python2.7/dist-packages/django/template/base.py", line 190, in __init__
    self.nodelist = engine.compile_string(template_string, origin)
  File "/usr/local/lib/python2.7/dist-packages/django/template/engine.py", line 261, in compile_string
    return parser.parse()
  File "/usr/local/lib/python2.7/dist-packages/django/template/base.py", line 341, in parse
    compiled_result = compile_func(self, token)
  File "/usr/local/lib/python2.7/dist-packages/django/template/defaulttags.py", line 872, in do_for
    nodelist_loop = parser.parse(('empty', 'endfor',))
  File "/usr/local/lib/python2.7/dist-packages/django/template/base.py", line 339, in parse
    self.invalid_block_tag(token, command, parse_until)
  File "/usr/local/lib/python2.7/dist-packages/django/template/base.py", line 394, in invalid_block_tag
    (command, get_text_list(["'%s'" % p for p in parse_until])))
TemplateSyntaxError: Invalid block tag: 'num_range', expected 'empty' or 'endfor'
2015-07-15 19:22:21,653 [ERROR] django.request: Internal Server Error: /polls/2/
Traceback (most recent call last):
  File "/usr/local/lib/python2.7/dist-packages/django/core/handlers/base.py", line 164, in get_response
    response = response.render()
  File "/usr/local/lib/python2.7/dist-packages/django/template/response.py", line 158, in render
    self.content = self.rendered_content
  File "/usr/local/lib/python2.7/dist-packages/django/template/response.py", line 133, in rendered_content
    template = self._resolve_template(self.template_name)
  File "/usr/local/lib/python2.7/dist-packages/django/template/response.py", line 88, in _resolve_template
    new_template = self.resolve_template(template)
  File "/usr/local/lib/python2.7/dist-packages/django/template/response.py", line 78, in resolve_template
    return loader.select_template(template, using=self.using)
  File "/usr/local/lib/python2.7/dist-packages/django/template/loader.py", line 64, in select_template
    return engine.get_template(template_name, dirs)
  File "/usr/local/lib/python2.7/dist-packages/django/template/backends/django.py", line 30, in get_template
    return Template(self.engine.get_template(template_name, dirs))
  File "/usr/local/lib/python2.7/dist-packages/django/template/engine.py", line 167, in get_template
    template, origin = self.find_template(template_name, dirs)
  File "/usr/local/lib/python2.7/dist-packages/django/template/engine.py", line 141, in find_template
    source, display_name = loader(name, dirs)
  File "/usr/local/lib/python2.7/dist-packages/django/template/loaders/base.py", line 13, in __call__
    return self.load_template(template_name, template_dirs)
  File "/usr/local/lib/python2.7/dist-packages/django/template/loaders/base.py", line 23, in load_template
    template = Template(source, origin, template_name, self.engine)
  File "/usr/local/lib/python2.7/dist-packages/django/template/base.py", line 190, in __init__
    self.nodelist = engine.compile_string(template_string, origin)
  File "/usr/local/lib/python2.7/dist-packages/django/template/engine.py", line 261, in compile_string
    return parser.parse()
  File "/usr/local/lib/python2.7/dist-packages/django/template/base.py", line 341, in parse
    compiled_result = compile_func(self, token)
  File "/usr/local/lib/python2.7/dist-packages/django/template/defaulttags.py", line 1163, in load
    (taglib, e))
TemplateSyntaxError: 'get_range' is not a valid tag library: Template library get_range not found, tried django.templatetags.get_range,django.contrib.admin.templatetags.get_range,django.contrib.staticfiles.templatetags.get_range
2015-07-15 20:45:10,762 [WARNING] django.request: Not Found: /favicon.ico
2015-07-15 20:59:57,062 [ERROR] django.request: Internal Server Error: /polls/1/
Traceback (most recent call last):
  File "/usr/local/lib/python2.7/dist-packages/django/core/handlers/base.py", line 164, in get_response
    response = response.render()
  File "/usr/local/lib/python2.7/dist-packages/django/template/response.py", line 158, in render
    self.content = self.rendered_content
  File "/usr/local/lib/python2.7/dist-packages/django/template/response.py", line 133, in rendered_content
    template = self._resolve_template(self.template_name)
  File "/usr/local/lib/python2.7/dist-packages/django/template/response.py", line 88, in _resolve_template
    new_template = self.resolve_template(template)
  File "/usr/local/lib/python2.7/dist-packages/django/template/response.py", line 78, in resolve_template
    return loader.select_template(template, using=self.using)
  File "/usr/local/lib/python2.7/dist-packages/django/template/loader.py", line 64, in select_template
    return engine.get_template(template_name, dirs)
  File "/usr/local/lib/python2.7/dist-packages/django/template/backends/django.py", line 30, in get_template
    return Template(self.engine.get_template(template_name, dirs))
  File "/usr/local/lib/python2.7/dist-packages/django/template/engine.py", line 167, in get_template
    template, origin = self.find_template(template_name, dirs)
  File "/usr/local/lib/python2.7/dist-packages/django/template/engine.py", line 141, in find_template
    source, display_name = loader(name, dirs)
  File "/usr/local/lib/python2.7/dist-packages/django/template/loaders/base.py", line 13, in __call__
    return self.load_template(template_name, template_dirs)
  File "/usr/local/lib/python2.7/dist-packages/django/template/loaders/base.py", line 23, in load_template
    template = Template(source, origin, template_name, self.engine)
  File "/usr/local/lib/python2.7/dist-packages/django/template/base.py", line 190, in __init__
    self.nodelist = engine.compile_string(template_string, origin)
  File "/usr/local/lib/python2.7/dist-packages/django/template/engine.py", line 261, in compile_string
    return parser.parse()
  File "/usr/local/lib/python2.7/dist-packages/django/template/base.py", line 341, in parse
    compiled_result = compile_func(self, token)
  File "/usr/local/lib/python2.7/dist-packages/django/template/defaulttags.py", line 1440, in url
    viewname = parser.compile_filter(bits[1])
  File "/usr/local/lib/python2.7/dist-packages/django/template/base.py", line 423, in compile_filter
    return FilterExpression(token, self)
  File "/usr/local/lib/python2.7/dist-packages/django/template/base.py", line 639, in __init__
    "from '%s'" % (token[upto:], token))
TemplateSyntaxError: Could not parse the remainder: ':index' from 'polls:index'
2015-07-15 21:05:34,727 [WARNING] django.request: Not Found: /favicon.ico
2015-07-15 21:33:47,620 [WARNING] django.request: Not Found: /favicon.ico
2015-07-15 21:33:49,586 [ERROR] django.request: Internal Server Error: /polls/
Traceback (most recent call last):
  File "/usr/local/lib/python2.7/dist-packages/django/core/handlers/base.py", line 164, in get_response
    response = response.render()
  File "/usr/local/lib/python2.7/dist-packages/django/template/response.py", line 158, in render
    self.content = self.rendered_content
  File "/usr/local/lib/python2.7/dist-packages/django/template/response.py", line 135, in rendered_content
    content = template.render(context, self._request)
  File "/usr/local/lib/python2.7/dist-packages/django/template/backends/django.py", line 74, in render
    return self.template.render(context)
  File "/usr/local/lib/python2.7/dist-packages/django/template/base.py", line 209, in render
    return self._render(context)
  File "/usr/local/lib/python2.7/dist-packages/django/template/base.py", line 201, in _render
    return self.nodelist.render(context)
  File "/usr/local/lib/python2.7/dist-packages/django/template/base.py", line 903, in render
    bit = self.render_node(node, context)
  File "/usr/local/lib/python2.7/dist-packages/django/template/debug.py", line 79, in render_node
    return node.render(context)
  File "/usr/local/lib/python2.7/dist-packages/django/template/defaulttags.py", line 507, in render
    six.reraise(*exc_info)
  File "/usr/local/lib/python2.7/dist-packages/django/template/defaulttags.py", line 493, in render
    url = reverse(view_name, args=args, kwargs=kwargs, current_app=current_app)
  File "/usr/local/lib/python2.7/dist-packages/django/core/urlresolvers.py", line 579, in reverse
    return force_text(iri_to_uri(resolver._reverse_with_prefix(view, prefix, *args, **kwargs)))
  File "/usr/local/lib/python2.7/dist-packages/django/core/urlresolvers.py", line 496, in _reverse_with_prefix
    (lookup_view_s, args, kwargs, len(patterns), patterns))
NoReverseMatch: Reverse for 'addQuestion' with arguments '()' and keyword arguments '{}' not found. 0 pattern(s) tried: []
2015-07-15 21:35:22,887 [ERROR] django.request: Internal Server Error: /polls/
Traceback (most recent call last):
  File "/usr/local/lib/python2.7/dist-packages/django/core/handlers/base.py", line 164, in get_response
    response = response.render()
  File "/usr/local/lib/python2.7/dist-packages/django/template/response.py", line 158, in render
    self.content = self.rendered_content
  File "/usr/local/lib/python2.7/dist-packages/django/template/response.py", line 135, in rendered_content
    content = template.render(context, self._request)
  File "/usr/local/lib/python2.7/dist-packages/django/template/backends/django.py", line 74, in render
    return self.template.render(context)
  File "/usr/local/lib/python2.7/dist-packages/django/template/base.py", line 209, in render
    return self._render(context)
  File "/usr/local/lib/python2.7/dist-packages/django/template/base.py", line 201, in _render
    return self.nodelist.render(context)
  File "/usr/local/lib/python2.7/dist-packages/django/template/base.py", line 903, in render
    bit = self.render_node(node, context)
  File "/usr/local/lib/python2.7/dist-packages/django/template/debug.py", line 79, in render_node
    return node.render(context)
  File "/usr/local/lib/python2.7/dist-packages/django/template/defaulttags.py", line 507, in render
    six.reraise(*exc_info)
  File "/usr/local/lib/python2.7/dist-packages/django/template/defaulttags.py", line 493, in render
    url = reverse(view_name, args=args, kwargs=kwargs, current_app=current_app)
  File "/usr/local/lib/python2.7/dist-packages/django/core/urlresolvers.py", line 579, in reverse
    return force_text(iri_to_uri(resolver._reverse_with_prefix(view, prefix, *args, **kwargs)))
  File "/usr/local/lib/python2.7/dist-packages/django/core/urlresolvers.py", line 496, in _reverse_with_prefix
    (lookup_view_s, args, kwargs, len(patterns), patterns))
NoReverseMatch: Reverse for 'addQuestion' with arguments '()' and keyword arguments '{}' not found. 0 pattern(s) tried: []
2015-07-15 21:35:39,406 [ERROR] django.request: Internal Server Error: /polls/
Traceback (most recent call last):
  File "/usr/local/lib/python2.7/dist-packages/django/core/handlers/base.py", line 119, in get_response
    resolver_match = resolver.resolve(request.path_info)
  File "/usr/local/lib/python2.7/dist-packages/django/core/urlresolvers.py", line 366, in resolve
    for pattern in self.url_patterns:
  File "/usr/local/lib/python2.7/dist-packages/django/core/urlresolvers.py", line 402, in url_patterns
    patterns = getattr(self.urlconf_module, "urlpatterns", self.urlconf_module)
  File "/usr/local/lib/python2.7/dist-packages/django/core/urlresolvers.py", line 396, in urlconf_module
    self._urlconf_module = import_module(self.urlconf_name)
  File "/usr/lib/python2.7/importlib/__init__.py", line 37, in import_module
    __import__(name)
  File "/home/george/djangoSite/djangoSite/urls.py", line 24, in <module>
    url(r'^polls/', include('polls.urls', namespace="polls")),
  File "/usr/local/lib/python2.7/dist-packages/django/conf/urls/__init__.py", line 33, in include
    urlconf_module = import_module(urlconf_module)
  File "/usr/lib/python2.7/importlib/__init__.py", line 37, in import_module
    __import__(name)
  File "/home/george/djangoSite/polls/urls.py", line 10
    url(r'(?P<question_id>[0-9]+)/addQuestion/$', views.addQuestion name='addQuestion')
                                                                       ^
SyntaxError: invalid syntax
2015-07-15 21:36:39,574 [ERROR] django.request: Internal Server Error: /polls/
Traceback (most recent call last):
  File "/usr/local/lib/python2.7/dist-packages/django/core/handlers/base.py", line 164, in get_response
    response = response.render()
  File "/usr/local/lib/python2.7/dist-packages/django/template/response.py", line 158, in render
    self.content = self.rendered_content
  File "/usr/local/lib/python2.7/dist-packages/django/template/response.py", line 135, in rendered_content
    content = template.render(context, self._request)
  File "/usr/local/lib/python2.7/dist-packages/django/template/backends/django.py", line 74, in render
    return self.template.render(context)
  File "/usr/local/lib/python2.7/dist-packages/django/template/base.py", line 209, in render
    return self._render(context)
  File "/usr/local/lib/python2.7/dist-packages/django/template/base.py", line 201, in _render
    return self.nodelist.render(context)
  File "/usr/local/lib/python2.7/dist-packages/django/template/base.py", line 903, in render
    bit = self.render_node(node, context)
  File "/usr/local/lib/python2.7/dist-packages/django/template/debug.py", line 79, in render_node
    return node.render(context)
  File "/usr/local/lib/python2.7/dist-packages/django/template/defaulttags.py", line 507, in render
    six.reraise(*exc_info)
  File "/usr/local/lib/python2.7/dist-packages/django/template/defaulttags.py", line 493, in render
    url = reverse(view_name, args=args, kwargs=kwargs, current_app=current_app)
  File "/usr/local/lib/python2.7/dist-packages/django/core/urlresolvers.py", line 579, in reverse
    return force_text(iri_to_uri(resolver._reverse_with_prefix(view, prefix, *args, **kwargs)))
  File "/usr/local/lib/python2.7/dist-packages/django/core/urlresolvers.py", line 496, in _reverse_with_prefix
    (lookup_view_s, args, kwargs, len(patterns), patterns))
NoReverseMatch: Reverse for 'addQuestion' with arguments '()' and keyword arguments '{}' not found. 1 pattern(s) tried: [u'polls/(?P<question_id>[0-9]+)/addQuestion/$']
2015-07-15 21:37:27,974 [ERROR] django.request: Internal Server Error: /polls/
Traceback (most recent call last):
  File "/usr/local/lib/python2.7/dist-packages/django/core/handlers/base.py", line 164, in get_response
    response = response.render()
  File "/usr/local/lib/python2.7/dist-packages/django/template/response.py", line 158, in render
    self.content = self.rendered_content
  File "/usr/local/lib/python2.7/dist-packages/django/template/response.py", line 135, in rendered_content
    content = template.render(context, self._request)
  File "/usr/local/lib/python2.7/dist-packages/django/template/backends/django.py", line 74, in render
    return self.template.render(context)
  File "/usr/local/lib/python2.7/dist-packages/django/template/base.py", line 209, in render
    return self._render(context)
  File "/usr/local/lib/python2.7/dist-packages/django/template/base.py", line 201, in _render
    return self.nodelist.render(context)
  File "/usr/local/lib/python2.7/dist-packages/django/template/base.py", line 903, in render
    bit = self.render_node(node, context)
  File "/usr/local/lib/python2.7/dist-packages/django/template/debug.py", line 79, in render_node
    return node.render(context)
  File "/usr/local/lib/python2.7/dist-packages/django/template/defaulttags.py", line 507, in render
    six.reraise(*exc_info)
  File "/usr/local/lib/python2.7/dist-packages/django/template/defaulttags.py", line 493, in render
    url = reverse(view_name, args=args, kwargs=kwargs, current_app=current_app)
  File "/usr/local/lib/python2.7/dist-packages/django/core/urlresolvers.py", line 579, in reverse
    return force_text(iri_to_uri(resolver._reverse_with_prefix(view, prefix, *args, **kwargs)))
  File "/usr/local/lib/python2.7/dist-packages/django/core/urlresolvers.py", line 496, in _reverse_with_prefix
    (lookup_view_s, args, kwargs, len(patterns), patterns))
NoReverseMatch: Reverse for 'addQuestion' with arguments '()' and keyword arguments '{}' not found. 1 pattern(s) tried: [u'polls/(?P<question_id>[0-9]+)/addQuestion/$']
2015-07-15 21:37:29,065 [ERROR] django.request: Internal Server Error: /polls/
Traceback (most recent call last):
  File "/usr/local/lib/python2.7/dist-packages/django/core/handlers/base.py", line 164, in get_response
    response = response.render()
  File "/usr/local/lib/python2.7/dist-packages/django/template/response.py", line 158, in render
    self.content = self.rendered_content
  File "/usr/local/lib/python2.7/dist-packages/django/template/response.py", line 135, in rendered_content
    content = template.render(context, self._request)
  File "/usr/local/lib/python2.7/dist-packages/django/template/backends/django.py", line 74, in render
    return self.template.render(context)
  File "/usr/local/lib/python2.7/dist-packages/django/template/base.py", line 209, in render
    return self._render(context)
  File "/usr/local/lib/python2.7/dist-packages/django/template/base.py", line 201, in _render
    return self.nodelist.render(context)
  File "/usr/local/lib/python2.7/dist-packages/django/template/base.py", line 903, in render
    bit = self.render_node(node, context)
  File "/usr/local/lib/python2.7/dist-packages/django/template/debug.py", line 79, in render_node
    return node.render(context)
  File "/usr/local/lib/python2.7/dist-packages/django/template/defaulttags.py", line 507, in render
    six.reraise(*exc_info)
  File "/usr/local/lib/python2.7/dist-packages/django/template/defaulttags.py", line 493, in render
    url = reverse(view_name, args=args, kwargs=kwargs, current_app=current_app)
  File "/usr/local/lib/python2.7/dist-packages/django/core/urlresolvers.py", line 579, in reverse
    return force_text(iri_to_uri(resolver._reverse_with_prefix(view, prefix, *args, **kwargs)))
  File "/usr/local/lib/python2.7/dist-packages/django/core/urlresolvers.py", line 496, in _reverse_with_prefix
    (lookup_view_s, args, kwargs, len(patterns), patterns))
NoReverseMatch: Reverse for 'addQuestion' with arguments '()' and keyword arguments '{}' not found. 1 pattern(s) tried: [u'polls/(?P<question_id>[0-9]+)/addQuestion/$']
2015-07-15 21:40:53,083 [WARNING] django.request: Not Found: /polls/addQuestion/
2015-07-15 21:42:56,757 [WARNING] django.request: Not Found: /polls/addQuestion/
2015-07-15 21:45:04,998 [WARNING] django.request: Not Found: /polls/addQuestion/
2015-07-15 21:46:44,201 [WARNING] django.request: Forbidden (CSRF token missing or incorrect.): /polls/addQuestion/
2015-07-15 21:47:38,175 [WARNING] django.request: Forbidden (CSRF token missing or incorrect.): /polls/addQuestion/
2015-07-15 21:47:47,377 [WARNING] django.request: Forbidden (CSRF token missing or incorrect.): /polls/addQuestion/
2015-07-15 21:50:39,381 [WARNING] django.request: Forbidden (CSRF token missing or incorrect.): /polls/addQuestion/
2015-07-15 21:51:01,844 [ERROR] django.request: Internal Server Error: /polls/addQuestion/
Traceback (most recent call last):
  File "/usr/local/lib/python2.7/dist-packages/django/core/handlers/base.py", line 132, in get_response
    response = wrapped_callback(request, *callback_args, **callback_kwargs)
  File "/home/george/djangoSite/polls/views.py", line 73, in addQuestion
    newQuestion.save()
  File "/usr/local/lib/python2.7/dist-packages/django/db/models/base.py", line 710, in save
    force_update=force_update, update_fields=update_fields)
  File "/usr/local/lib/python2.7/dist-packages/django/db/models/base.py", line 738, in save_base
    updated = self._save_table(raw, cls, force_insert, force_update, using, update_fields)
  File "/usr/local/lib/python2.7/dist-packages/django/db/models/base.py", line 822, in _save_table
    result = self._do_insert(cls._base_manager, using, fields, update_pk, raw)
  File "/usr/local/lib/python2.7/dist-packages/django/db/models/base.py", line 861, in _do_insert
    using=using, raw=raw)
  File "/usr/local/lib/python2.7/dist-packages/django/db/models/manager.py", line 127, in manager_method
    return getattr(self.get_queryset(), name)(*args, **kwargs)
  File "/usr/local/lib/python2.7/dist-packages/django/db/models/query.py", line 920, in _insert
    return query.get_compiler(using=using).execute_sql(return_id)
  File "/usr/local/lib/python2.7/dist-packages/django/db/models/sql/compiler.py", line 974, in execute_sql
    cursor.execute(sql, params)
  File "/usr/local/lib/python2.7/dist-packages/django/db/backends/utils.py", line 79, in execute
    return super(CursorDebugWrapper, self).execute(sql, params)
  File "/usr/local/lib/python2.7/dist-packages/django/db/backends/utils.py", line 64, in execute
    return self.cursor.execute(sql, params)
  File "/usr/local/lib/python2.7/dist-packages/django/db/backends/mysql/base.py", line 129, in execute
    six.reraise(utils.IntegrityError, utils.IntegrityError(*tuple(e.args)), sys.exc_info()[2])
  File "/usr/local/lib/python2.7/dist-packages/django/db/backends/mysql/base.py", line 124, in execute
    return self.cursor.execute(query, args)
  File "/usr/lib/python2.7/dist-packages/MySQLdb/cursors.py", line 174, in execute
    self.errorhandler(self, exc, value)
  File "/usr/lib/python2.7/dist-packages/MySQLdb/connections.py", line 36, in defaulterrorhandler
    raise errorclass, errorvalue
IntegrityError: (1048, "Column 'pub_date' cannot be null")
2015-07-15 21:52:15,218 [ERROR] django.request: Internal Server Error: /polls/addQuestion/
Traceback (most recent call last):
  File "/usr/local/lib/python2.7/dist-packages/django/core/handlers/base.py", line 132, in get_response
    response = wrapped_callback(request, *callback_args, **callback_kwargs)
  File "/home/george/djangoSite/polls/views.py", line 71, in addQuestion
    newQuestion = Question(question_text=request.POST['newQuestion'], pub_date=timezone.now())
  File "/usr/local/lib/python2.7/dist-packages/django/utils/datastructures.py", line 322, in __getitem__
    raise MultiValueDictKeyError(repr(key))
MultiValueDictKeyError: "'newQuestion'"
2015-07-15 22:06:00,470 [WARNING] django.request: Not Found: /favicon.ico
2015-07-15 22:06:00,493 [WARNING] django.request: Not Found: /favicon.ico
2015-07-15 22:06:00,510 [WARNING] django.request: Not Found: /favicon.ico
